{
  "xsize": 16,
  "zsize": 16,
  "slices": [
    [
      "#$$#$$#$$#$$#$$#",
      "$##############$",
      "$###1##########$",
      "################",
      "$#####1########$",
      "$##############$",
      "################",
      "$##############$",
      "$##############$",
      "#######l########",
      "$##############$",
      "$##############$",
      "################",
      "$##############$",
      "$##############$",
      "#$$#$$#$$#$$#$$#"
    ],
    [
      "################",
      "#        #     #",
      "#        #   # #",
      "#        #   # #",
      "#        #     #",
      "#        #     #",
      "##########     #",
      "#              #",
      "#              #",
      "#      l       #",
      "#     ###      #",
      "#              #",
      "#              #",
      "#              #",
      "#FF            #",
      "################"
    ],
    [
      "#aa#aa#aa#aa#aa#",
      "a        :     a",
      "a        :   * a",
      "#        :   * #",
      "a        :     a",
      "a        :     a",
      "#::::::::#     #",
      "a              a",
      "a              a",
      "#      l       #",
      "a     ###      a",
      "a      T       a",
      "#              #",
      "a              a",
      "a              a",
      "#aa#aa#aa#aa#aa#"
    ],
    [
      "#aa#aa#aa#aa#aa#",
      "a        :     a",
      "a        :     a",
      "#        :     #",
      "a        :     a",
      "a        :     a",
      "#::::::::#     #",
      "a              a",
      "a              a",
      "#      l       #",
      "a     ###      a",
      "a              a",
      "#              #",
      "a              a",
      "a              a",
      "#aa#aa#aa#aa#aa#"
    ],
    [
      "################",
      "################",
      "################",
      "################",
      "################",
      "################",
      "################",
      "################",
      "################",
      "#######l########",
      "################",
      "################",
      "################",
      "################",
      "################",
      "################"
    ],
    [
      "################",
      "################",
      "################",
      "################",
      "################",
      "################",
      "################",
      "################",
      "################",
      "#######l########",
      "################",
      "################",
      "################",
      "################",
      "################",
      "################"
    ]
  ]
}