{
  "xsize": 16,
  "zsize": 16,
  "slices": [
    [
      "##   #aaaa#   ##",
      "######QSQS######",
      "SQSQSQSQSQSQSQ# ",
      "QSQSQSQSQSQSQS# ",
      "SQSQSQSQSQSQSQ# ",
      "QSQSQSQSQSQSQS##",
      "SQSQSQSQSQSQSQSa",
      "QSQSQSQSQSQSQSQa",
      "SQSQSQSQSQSQSQSa",
      "QSQSQSQSQSQSQSQa",
      "SQSQSQSQSQSQSQ##",
      "QSQSQSQSQSQSQS# ",
      "SQSQSQSQSQSQSQ# ",
      "QSQSQSQSQSQSQS# ",
      "SQSQSQSQSQSQSQ##",
      "QSQSQSQSQSQSQS##"
    ],
    [
      "##   #aaaa#   ##",
      "##aaa#    #aaa##",
      "              a ",
      "              a ",
      "              a ",
      "   +++++++    ##",
      "   +QQQQQ+     a",
      "   +Q1QQQ+     a",
      "   +QQQ1Q+     a",
      "   +QQQQQ+     a",
      "   +++++++    ##",
      "              a ",
      "              a ",
      "              a ",
      "              ##",
      "              ##"
    ],
    [
      "##   #aaaa#   ##",
      "##aaa#    #aaa##",
      "              a ",
      "              a ",
      "              a ",
      "   +++++++    ##",
      "   +QQQQQ+     a",
      "   +QQQQQ+     a",
      "   +QQQQQ+     a",
      "   +QQQQQ+     a",
      "   +++++++    ##",
      "              a ",
      "              a ",
      "              a ",
      "              ##",
      "              ##"
    ],
    [
      "##   #aaaa#   ##",
      "##aaa#    #aaa##",
      "              a ",
      "              a ",
      "              a ",
      "   +++++++    ##",
      "   +QQQQQ+     a",
      "   +QQQQQ+     a",
      "   +QQQQQ+     a",
      "   +QQQQQ+     a",
      "   +++++++    ##",
      "              a ",
      "              a ",
      "              a ",
      "              ##",
      "              ##"
    ],
    [
      "##   #aaaa#   ##",
      "##aaa#    #aaa##",
      "              a ",
      "              a ",
      "              a ",
      "   +++++++    ##",
      "   +QQQQQ+     a",
      "   +QQQQQ+     a",
      "   +QQQQQ+     a",
      "   +QQQQQ+     a",
      "   +++++++    ##",
      "              a ",
      "              a ",
      "              a ",
      "              ##",
      "              ##"
    ],
    [
      "##   #aaaa#   ##",
      "################",
      "############### ",
      "############### ",
      "############### ",
      "################",
      "###############a",
      "###############a",
      "###############a",
      "###############a",
      "################",
      "############### ",
      "############### ",
      "############### ",
      "################",
      "################"
    ]
  ]
}