{
  "xsize": 16,
  "zsize": 16,
  "palette": {
    "palette": [
      {
        "char": "p",
        "block": "minecraft:gray_concrete"
      },
      {
        "char": "r",
        "block": "minecraft:red_concrete"
      },
      {
        "char": "a",
        "block": "minecraft:iron_door[facing=north,half=lower,hinge=left]"
      },
      {
        "char": "j",
        "block": "minecraft:iron_door[facing=north,half=upper,hinge=left]"
      },
      {
        "char": "n",
        "block": "minecraft:lantern[hanging=true]"
      },
      {
        "char": "b",
        "block": "minecraft:iron_bars"
      }
    ]
  },
  "slices": [
    [
      "pppppppppppppppp",
      "pppppppppppppppp",
      "pppppppppppppppp",
      "pppppppppppppppp",
      "pppppppppppppppp",
      "pppppppppppppppp",
      "pppppppppppppppp",
      "pppppppppppppppp",
      "pppppppppppppppp",
      "pppppppppppppppp",
      "pppppppppppppppp",
      "pppppppppppppppp",
      "pppppppppppppppp",
      "pppppppppppppppp",
      "pppppppppppppppp",
      "pppppppppppppppp"
    ],
    [
      "                ",
      "b               ",
      "b               ",
      "bBQQQQaaQQQQQQB ",
      "bB            B ",
      "bB  .-  .-    B ",
      "bB            B ",
      "bB  .-  .-    B ",
      "bB            B ",
      "bB  .-  .-    B ",
      "bB            B ",
      "bB  LLLL      B ",
      "bB  C   F     B ",
      "bBQQQQQQQQQQQQB ",
      "bBQQQQQQQQQQQQB ",
      "bbbbbbbbbbbbbbbb"
    ],
    [
      "                ",
      "b               ",
      "b               ",
      "bBYYYYjjYYYYYYB ",
      "bB            B ",
      "bB  --  --    B ",
      "bB            B ",
      "bB  --  --    B ",
      "bB            B ",
      "bB  --  --    B ",
      "bB            B ",
      "bB            B ",
      "bB            B ",
      "bBYYYYYYYYYYYYB ",
      "bBQQQQQQQQQQQQB ",
      "bbbbbbbbbbbbbbbb"
    ],
    [
      "                ",
      "                ",
      "                ",
      " BYYYYYYYYYYYYB ",
      " B            B ",
      " B            B ",
      " B            B ",
      " B            B ",
      " B            B ",
      " B            B ",
      " B            B ",
      " B            B ",
      " B            B ",
      " BYYYYYYYYYYYYB ",
      " BQQQQQQQQQQQQB ",
      "                "
    ],
    [
      "                ",
      "                ",
      "                ",
      " BQQQQQQQQQQQQB ",
      " B            B ",
      " B     n      B ",
      " B            B ",
      " B     n      B ",
      " B            B ",
      " B     n      B ",
      " B            B ",
      " B            B ",
      " B            B ",
      " BQQQQQQQQQQQQB ",
      " BQQQQQQQQQQQQB ",
      "                "
    ],
    [
      "                ",
      "                ",
      "                ",
      " QQQQQQQQQQQQQQ ",
      " QQQQQQQQQQQQQQ ",
      " QQQQQQQQQQQQQQ ",
      " QQQQQQQQQQQQQQ ",
      " QQQQQQQQQQQQQQ ",
      " QQQQQQQQQQQQQQ ",
      " QQQQQQQQQQQQQQ ",
      " QQQQQQQQQQQQQQ ",
      " QQQQQQQQQQQQQQ ",
      " QQQQQQQQQQQQQQ ",
      " QQQQQQQQQQQQQQ ",
      " QQQQQQQQQQQQQQ ",
      "                "
    ],
    [
      "                ",
      "                ",
      "                ",
      "     rrrrrr     ",
      "     rrrrrr     ",
      "                ",
      "                ",
      "                ",
      "                ",
      "                ",
      "                ",
      "                ",
      "                ",
      "                ",
      "                ",
      "                "
    ]
  ]
}
