{
  "xsize": 16,
  "zsize": 16,
  "palette": {
    "palette": [
      {
        "char": "p",
        "block": "minecraft:gray_concrete"
      },
      {
        "char": "r",
        "block": "minecraft:red_concrete"
      },
      {
        "char": "a",
        "block": "minecraft:iron_door[facing=north,half=lower,hinge=left]"
      },
      {
        "char": "j",
        "block": "minecraft:iron_door[facing=north,half=upper,hinge=left]"
      },
      {
        "char": "n",
        "block": "minecraft:lantern[hanging=true]"
      }
    ]
  },
  "slices": [
    [
      "pppppppppppppppp",
      "pppppppppppppppp",
      "pppppppppppppppp",
      "pppppppppppppppp",
      "pppppppppppppppp",
      "pppppppppppppppp",
      "pppppppppppppppp",
      "pppppppppppppppp",
      "pppppppppppppppp",
      "pppppppppppppppp",
      "pppppppppppppppp",
      "pppppppppppppppp",
      "pppppppppppppppp",
      "pppppppppppppppp",
      "pppppppppppppppp",
      "pppppppppppppppp"
    ],
    [
      "                ",
      "                ",
      "                ",
      " BQQQQaaQQQQQQB ",
      " B            B ",
      " B  .-  .-    B ",
      " B            B ",
      " B  .-  .-    B ",
      " B            B ",
      " B  .-  .-    B ",
      " B            B ",
      " B  LLLL      B ",
      " B  C   F     B ",
      " BQQQQQQQQQQQQB ",
      " BQQQQQQQQQQQQB ",
      "                "
    ],
    [
      "                ",
      "                ",
      "                ",
      " BYYYYjjYYYYYYB ",
      " B            B ",
      " B  --  --    B ",
      " B            B ",
      " B  --  --    B ",
      " B            B ",
      " B  --  --    B ",
      " B            B ",
      " B            B ",
      " B            B ",
      " BYYYYYYYYYYYYB ",
      " BQQQQQQQQQQQQB ",
      "                "
    ],
    [
      "                ",
      "                ",
      "                ",
      " BYYYYYYYYYYYYB ",
      " B            B ",
      " B            B ",
      " B            B ",
      " B            B ",
      " B            B ",
      " B            B ",
      " B            B ",
      " B            B ",
      " B            B ",
      " BYYYYYYYYYYYYB ",
      " BQQQQQQQQQQQQB ",
      "                "
    ],
    [
      "                ",
      "                ",
      "                ",
      " BQQQQQQQQQQQQB ",
      " B            B ",
      " B     n      B ",
      " B            B ",
      " B     n      B ",
      " B            B ",
      " B     n      B ",
      " B            B ",
      " B            B ",
      " B            B ",
      " BQQQQQQQQQQQQB ",
      " BQQQQQQQQQQQQB ",
      "                "
    ],
    [
      "                ",
      "                ",
      "                ",
      " QQQQQQQQQQQQQQ ",
      " QQQQQQQQQQQQQQ ",
      " QQQQQQQQQQQQQQ ",
      " QQQQQQQQQQQQQQ ",
      " QQQQQQQQQQQQQQ ",
      " QQQQQQQQQQQQQQ ",
      " QQQQQQQQQQQQQQ ",
      " QQQQQQQQQQQQQQ ",
      " QQQQQQQQQQQQQQ ",
      " QQQQQQQQQQQQQQ ",
      " QQQQQQQQQQQQQQ ",
      " QQQQQQQQQQQQQQ ",
      "                "
    ],
    [
      "                ",
      "                ",
      "                ",
      "     rrrrrr     ",
      "     rrrrrr     ",
      "                ",
      "                ",
      "                ",
      "                ",
      "                ",
      "                ",
      "                ",
      "                ",
      "                ",
      "                ",
      "                "
    ]
  ]
}
