{
  "xsize": 16,
  "zsize": 16,
  "slices": [
    [
      "#SS#QQQQQQQQQQQQ",
      "#SS#QQQQQQQQQQQQ",
      "#SS#QQQQQQQQQQQQ",
      "#SS#QQQQQQQQQQQQ",
      "#SS#QQQQQQQQQQQQ",
      "#SS#QQQQQQQQQQQQ",
      "#SS#QQQQQQQQQQQQ",
      "#SS#QQQQQQQQQQQQ",
      "#SS#QQQQQQQQQQQQ",
      "#SS#QQQQQQQQQQQQ",
      "#SS#QQQQQQQQQQQQ",
      "#SS#QQQQQQQQQQQQ",
      "#SS#############",
      "#SSSSSSSSSSSSSSS",
      "#SSSSSSSSSSSSSSS",
      "################"
    ],
    [
      "a               ",
      "a               ",
      "a               ",
      "#               ",
      "a      LLLL     ",
      "a     QQQQQQ    ",
      "a     QLLLLQ    ",
      "a     Q    Q    ",
      "#               ",
      "a     Q    Q    ",
      "a     QLLLLQ    ",
      "a     QQQQQQ    ",
      "a      LLLL     ",
      "#               ",
      "a               ",
      "aa#aaaa#aaaa#aaa"
    ],
    [
      "a               ",
      "a               ",
      "a               ",
      "#               ",
      "a               ",
      "a      **       ",
      "a               ",
      "a               ",
      "#               ",
      "a               ",
      "a               ",
      "a        * *    ",
      "a               ",
      "#               ",
      "a               ",
      "aa#aaaa#aaaa#aaa"
    ],
    [
      "a               ",
      "a               ",
      "a               ",
      "#               ",
      "a               ",
      "a               ",
      "a               ",
      "a               ",
      "#               ",
      "a               ",
      "a               ",
      "a               ",
      "a               ",
      "#               ",
      "a               ",
      "aa#aaaa#aaaa#aaa"
    ],
    [
      "#               ",
      "#               ",
      "#               ",
      "#               ",
      "#               ",
      "#               ",
      "#               ",
      "#               ",
      "#               ",
      "#               ",
      "#               ",
      "#               ",
      "#               ",
      "#               ",
      "#               ",
      "################"
    ],
    [
      "################",
      "################",
      "################",
      "################",
      "################",
      "################",
      "################",
      "################",
      "################",
      "################",
      "################",
      "################",
      "################",
      "################",
      "################",
      "################"
    ]
  ]
}