{
  "meta": [
    {
      "key": "nowater",
      "boolean": true
    }
  ],
  "refpalette": "rails",
  "xsize": 16,
  "zsize": 16,
  "slices": [
    [
      "      YYYYY     ",
      "      YYYYY     ",
      "      YYYYY     ",
      "      YYYYY     ",
      "      YYYYY     ",
      "      YYYYY     ",
      "      YYYYY     ",
      "      yyyyy     ",
      "      YYYYY     ",
      "      YYYYY     ",
      "      YYYYY     ",
      "      YYYYY     ",
      "      YYYYY     ",
      "      YYYYY     ",
      "      YYYYY     ",
      "      YYYYY     "
    ],
    [
      "    YY~~~~~YY   ",
      "    YY~~~~~YY   ",
      "    YY~~~~~YY   ",
      "    YY~~~~~YY   ",
      "    YY~~~~~YY   ",
      "    YY~~~~~YY   ",
      "    YY~~~~~YY   ",
      "    yy~~~~~yy   ",
      "    YY~~~~~YY   ",
      "    YY~~~~~YY   ",
      "    YY~~~~~YY   ",
      "    YY~~~~~YY   ",
      "    YY~~~~~YY   ",
      "    YY~~~~~YY   ",
      "    YY~~~~~YY   ",
      "    YY~~~~~YY   "
    ],
    [
      "   Y~~QQQQQ~~Y  ",
      "   Y~~QQQQQ~~Y  ",
      "   Y~~QQQQQ~~Y  ",
      "   Y~~QQQQQ~~Y  ",
      "   Y~~QQQQQ~~Y  ",
      "   Y~~QQQQQ~~Y  ",
      "   Y~~QQQQQ~~Y  ",
      "   y~~QQQQQ~~y  ",
      "   Y~~QQQQQ~~Y  ",
      "   Y~~QQQQQ~~Y  ",
      "   Y~~QQQQQ~~Y  ",
      "   Y~~QQQQQ~~Y  ",
      "   Y~~QQQQQ~~Y  ",
      "   Y~~QQQQQ~~Y  ",
      "   Y~~QQQQQ~~Y  ",
      "   Y~~QQQQQ~~Y  "
    ],
    [
      "  Y~~~QQkQQ~~~Y ",
      "  Y~~~QQkQQ~~~Y ",
      "  Y~~~QQkQQ~~~Y ",
      "  Y~~~QQkQQ~~~Y ",
      "  Y~~~QQkQQ~~~Y ",
      "  Y~~~QQkQQ~~~Y ",
      "  Y~~~QQkQQ~~~Y ",
      "  y~~~QQkQQ~~~y ",
      "  Y~~~QgmgQ~~~Y ",
      "  Y~~~QQkQQ~~~Y ",
      "  Y~~~QQkQQ~~~Y ",
      "  Y~~~QQkQQ~~~Y ",
      "  Y~~~QQkQQ~~~Y ",
      "  Y~~~QQkQQ~~~Y ",
      "  Y~~~QQkQQ~~~Y ",
      "  Y~~~QQkQQ~~~Y "
    ],
    [
      " Y~~~~~~~~~~~~~Y",
      " Y~~~~~~~~~~~~~Y",
      " Y~~~~~~~~~~~~~Y",
      " Y~~~~~~~~~~~~~Y",
      " Y~~~~~~~~~~~~~Y",
      " Y~~~~~~~~~~~~~Y",
      " Y~~~~~~~~~~~~~Y",
      " y~~~~~~~~~~~~~y",
      " Y~~~~~~~~~~~~~Y",
      " Y~~~~~~~~~~~~~Y",
      " Y~~~~~~~~~~~~~Y",
      " Y~~~~~~~~~~~~~Y",
      " Y~~~~~~~~~~~~~Y",
      " Y~~~~~~~~~~~~~Y",
      " Y~~~~~~~~~~~~~Y",
      " Y~~~~~~~~~~~~~Y"
    ],
    [
      " Y~~~~~~~~~~~~~Y",
      " Y~~~~~~~~~~~~~Y",
      " Y~~~~~~~~~~~~~Y",
      " Y~~~~~~~~~~~~~Y",
      " Y~~~~~~~~~~~~~Y",
      " Y~~~~~~~~~~~~~Y",
      " Y~~~~~~~~~~~~~Y",
      " y~~~~~~~~~~~~~y",
      " Y~~~~~~~~~~~~~Y",
      " Y~~~~~~~~~~~~~Y",
      " Y~~~~~~~~~~~~~Y",
      " Y~~~~~~~~~~~~~Y",
      " Y~~~~~~~~~~~~~Y",
      " Y~~~~~~~~~~~~~Y",
      " Y~~~~~~~~~~~~~Y",
      " Y~~~~~~~~~~~~~Y"
    ],
    [
      "  Y~~~~~~~~~~~Y ",
      "  Y~~~~~~~~~~~Y ",
      "  Y~~~~~~~~~~~Y ",
      "  Y~~~~~~~~~~~Y ",
      "  Y~~~~~~~~~~~Y ",
      "  Y~~~~~~~~~~~Y ",
      "  Y~~~~~~~~~~~Y ",
      "  y~~~~~~~~~~~y ",
      "  Y~~~~~~~~~~~Y ",
      "  Y~~~~~~~~~~~Y ",
      "  Y~~~~~~~~~~~Y ",
      "  Y~~~~~~~~~~~Y ",
      "  Y~~~~~~~~~~~Y ",
      "  Y~~~~~~~~~~~Y ",
      "  Y~~~~~~~~~~~Y ",
      "  Y~~~~~~~~~~~Y "
    ],
    [
      "   Y~~~~~~~~~Y  ",
      "   Y~~~~~~~~~Y  ",
      "   Y~~~~~~~~~Y  ",
      "   Y~~~~~~~~~Y  ",
      "   Y~~~~~~~~~Y  ",
      "   Y~~~~~~~~~Y  ",
      "   Y~~~~~~~~~Y  ",
      "   y~~~~~~~~~y  ",
      "   Y~~~~~~~~~Y  ",
      "   Y~~~~~~~~~Y  ",
      "   Y~~~~~~~~~Y  ",
      "   Y~~~~~~~~~Y  ",
      "   Y~~~~~~~~~Y  ",
      "   Y~~~~~~~~~Y  ",
      "   Y~~~~~~~~~Y  ",
      "   Y~~~~~~~~~Y  "
    ],
    [
      "    YY~~~~~YY   ",
      "    YY~~~~~YY   ",
      "    YY~~~~~YY   ",
      "    YY~~~~~YY   ",
      "    YY~~~~~YY   ",
      "    YY~~~~~YY   ",
      "    YY~~~~~YY   ",
      "    yy~~~~~yy   ",
      "    YY~~~~~YY   ",
      "    YY~~~~~YY   ",
      "    YY~~~~~YY   ",
      "    YY~~~~~YY   ",
      "    YY~~~~~YY   ",
      "    YY~~~~~YY   ",
      "    YY~~~~~YY   ",
      "    YY~~~~~YY   "
    ],
    [
      "      YYYYY     ",
      "      YYYYY     ",
      "      YYYYY     ",
      "      YYYYY     ",
      "      YYYYY     ",
      "      YYYYY     ",
      "      YYYYY     ",
      "      yyyyy     ",
      "      YYYYY     ",
      "      YYYYY     ",
      "      YYYYY     ",
      "      YYYYY     ",
      "      YYYYY     ",
      "      YYYYY     ",
      "      YYYYY     ",
      "      YYYYY     "
    ]
  ]
}