{
  "meta": [
    {
      "key": "nowater",
      "boolean": true
    }
  ],
  "refpalette": "rails",
  "xsize": 16,
  "zsize": 16,
  "slices": [
    [
      "yyyyyyyyyyyyyyyy",
      "yyyyyyyyyyyyyyyy",
      "yyyyyyyyyyyyyyyy",
      "yyyyyyyyyyyyyyyy",
      "yyyyyyyyyyyyyyyy",
      "yyyyyyyyyyyyyyyy",
      "yyyyyyyyyyyyyyyy",
      "yyyyyyyyyyyyyyyy",
      "yyyyyyyyyyyyyyyy",
      "yyyyyyyyyyyyyyyy",
      "yyyyyyyyyyyyyyyy",
      "yyyyyyyyyyyyyyyy",
      "yyyyyyyyyyyyyyyy",
      "yyyyyyyyyyyyyyyy",
      "yyyyyyyyyyyyyyyy",
      "yyyyyyyyyyyyyyyy"
    ],
    [
      "yyyyyyyyyyyyyyyy",
      "yyyyyyyyyyyyyyyy",
      "yyyyyyyyyyyyyyyy",
      "yyyyyyyyyyyyyyyy",
      "yyyyyyyyyyyyyyyy",
      "yyyyyyyyyyyyyyyy",
      "yyyyyyyyyyyyyyyy",
      "yyyyyyyyyyyyyyyy",
      "yyyyyyyyyyyyyyyy",
      "yyyyyyyyyyyyyyyy",
      "yyyyyyyyyyyyyyyy",
      "yyyyyyyyyyyyyyyy",
      "yyyyyyyyyyyyyyyy",
      "yyyyyyyyyyyyyyyy",
      "yyyyyyyyyyyyyyyy",
      "yyyyyyyyyyyyyyyy"
    ],
    [
      "yyyyyyQQQQQyyyyy",
      "yyyyyyQQQQQyyyyy",
      "yyyyyyQQQQQyyyyy",
      "yyyyyyQQQQQyyyyy",
      "yyyyyyQQQQQyyyyy",
      "yyyyyyQQQQQyyyyy",
      "yyyyyyQQQQQyyyyy",
      "yyyyyyQQQQQyyyyy",
      "yyyyyyQQQQQyyyyy",
      "yyyyyyQQQQQyyyyy",
      "yyyyyyQQQQQyyyyy",
      "yyyyyyQQQQQyyyyy",
      "yyyyyyyyyyyyyyyy",
      "yyyyyyyyyyyyyyyy",
      "yyyyyyyyyyyyyyyy",
      "yyyyyyyyyyyyyyyy"
    ],
    [
      "w     QQkQQ    w",
      "w     QQkQQ    w",
      "w     QQkQQ    w",
      "w     QQkQQ    w",
      "w     QQkQQ    w",
      "w     QQkQQ    w",
      "w     QQkQQ    w",
      "w     QQkQQ    w",
      "w     QgmgQ    w",
      "w     QQkQQ    w",
      "w     QQkQQ    w",
      "w     QQQQQ    w",
      "w              w",
      "w              w",
      "w              w",
      "wwwwwwwwwwwwwwww"
    ]
  ]
}