{
  "meta": [
    {
      "key": "nowater",
      "boolean": true
    }
  ],
  "refpalette": "rails",
  "xsize": 16,
  "zsize": 16,
  "slices": [
    [
      "      YYYYY     ",
      "      YYYYY     ",
      "      YYYYY     ",
      "      YYYYY     ",
      "      YYYYY     ",
      "      YYYYY     ",
      "YYYYYYYYYYYYYYYY",
      "YYYYYYYYYYYYYYYY",
      "YYYYYYYYYYYYYYYY",
      "YYYYYYYYYYYYYYYY",
      "YYYYYYYYYYYYYYYY",
      "      YYYYY     ",
      "      YYYYY     ",
      "      YYYYY     ",
      "      YYYYY     ",
      "      YYYYY     "
    ],
    [
      "    YY~~~~~YY   ",
      "    YY~~~~~YY   ",
      "    YY~~~~~YY   ",
      "    YY~~~~~YY   ",
      "YYYYYY~~~~~YYYYY",
      "YYYYYY~~~~~YYYYY",
      "~~~~~~~~~~~~~~~~",
      "~~~~~~~~~~~~~~~~",
      "~~~~~~~~~~~~~~~~",
      "~~~~~~~~~~~~~~~~",
      "~~~~~~~~~~~~~~~~",
      "YYYYYY~~~~~YYYYY",
      "YYYYYY~~~~~YYYYY",
      "    YY~~~~~YY   ",
      "    YY~~~~~YY   ",
      "    YY~~~~~YY   "
    ],
    [
      "   Y~~QQQQQ~~Y  ",
      "   Y~~QQQQQ~~Y  ",
      "   Y~~QQQQQ~~Y  ",
      "YYYY~~QQQQQ~~YYY",
      "~~~~~~QQQQQ~~~~~",
      "~~~~~~QQQQQ~~~~~",
      "QQQQQQQQQQQQQQQQ",
      "QQQQQQQQQQQQQQQQ",
      "QQQQQQQQQQQQQQQQ",
      "QQQQQQQQQQQQQQQQ",
      "QQQQQQQQQQQQQQQQ",
      "~~~~~~QQQQQ~~~~~",
      "~~~~~~QQQQQ~~~~~",
      "YYYY~~QQQQQ~~YYY",
      "   Y~~QQQQQ~~Y  ",
      "   Y~~QQQQQ~~Y  "
    ],
    [
      "  Y~~~QQkQQ~~~Y ",
      "  Y~~~QQkQQ~~~Y ",
      "YYY~~~QgmgQ~~~YY",
      "~~~~~~QQEQQ~~~~~",
      "~~~~~~QQQQQ~~~~~",
      "~~~~~~QQQQQ~~~~~",
      "QQQQQQQQQQQQQQQQ",
      "QQQQQQQQgQQQQQQQ",
      "eeeeeeeefeeeeeee",
      "QQQQQQQQgQQQQQQQ",
      "QQQQQQQQQQQQQQQQ",
      "~~~~~~QQQQQ~~~~~",
      "~~~~~~QQQQQ~~~~~",
      "~~~~~~QQHQQ~~~~~",
      "YYY~~~QgmgQ~~~YY",
      "  Y~~~QQkQQ~~~Y "
    ],
    [
      " Y~~~~~~~~~~~~~Y",
      "YY~~~~~~~~~~~~~Y",
      "~~~~~~~~~~~~~~~~",
      "~~~~~~~)~)~~~~~~",
      "~~~~~~~QEQ~~~~~~",
      "~~~~~~~QQQ~~~~~~",
      "~~~~~~~~~~~~~~~~",
      "~~~~~~~~~~~~~~~~",
      "~~~~~~~~~~~~~~~~",
      "~~~~~~~~~~~~~~~~",
      "~~~~~~~~~~~~~~~~",
      "~~~~~~~QQQ~~~~~~",
      "~~~~~~~QHQ~~~~~~",
      "~~~~~~~(~(~~~~~~",
      "~~~~~~~~~~~~~~~~",
      "YY~~~~~~~~~~~~~Y"
    ],
    [
      " Y~~~~~~~~~~~~~Y",
      "YY~~~~~~~~~~~~~Y",
      "~~~~~~~~~~~~~~~~",
      "~~~~~~~~~~~~~~~~",
      "~~~~~~~)~)~~~~~~",
      "~~~~~~~QEQ~~~~~~",
      "~~~~~~~~Q~~~~~~~",
      "~~~~~~~~Q~~~~~~~",
      "~~~~~~~~Q~~~~~~~",
      "~~~~~~~~Q~~~~~~~",
      "~~~~~~~~Q~~~~~~~",
      "~~~~~~~QHQ~~~~~~",
      "~~~~~~~(~(~~~~~~",
      "~~~~~~~~~~~~~~~~",
      "~~~~~~~~~~~~~~~~",
      "YY~~~~~~~~~~~~~Y"
    ],
    [
      "  Y~~~~~~~~~~~Y ",
      "  Y~~~~~~~~~~~Y ",
      "YYY~~~~~~~~~~~YY",
      "~~~~~~~~~~~~~~~~",
      "~~~~~~~~~~~~~~~~",
      "~~~~~~~)~)~~~~~~",
      "~~~~~~~QkQ~~~~~~",
      "~~~~~~~QkQ~~~~~~",
      "~~~~~~~QkQ~~~~~~",
      "~~~~~~~QkQ~~~~~~",
      "~~~~~~~QkQ~~~~~~",
      "~~~~~~~(~(~~~~~~",
      "~~~~~~~~~~~~~~~~",
      "~~~~~~~~~~~~~~~~",
      "YYY~~~~~~~~~~~YY",
      "  Y~~~~~~~~~~~Y "
    ],
    [
      "   Y~~~~~~~~~Y  ",
      "   Y~~~~~~~~~Y  ",
      "   Y~~~~~~~~~Y  ",
      "YYYY~~~~~~~~~YYY",
      "~~~~~~~~~~~~~~~~",
      "~~~~~~~~~~~~~~~~",
      "~~~~~~~~~~~~~~~~",
      "~~~~~~~~~~~~~~~~",
      "~~~~~~~~~~~~~~~~",
      "~~~~~~~~~~~~~~~~",
      "~~~~~~~~~~~~~~~~",
      "~~~~~~~~~~~~~~~~",
      "~~~~~~~~~~~~~~~~",
      "YYYY~~~~~~~~~YYY",
      "   Y~~~~~~~~~Y  ",
      "   Y~~~~~~~~~Y  "
    ],
    [
      "    YY~~~~~YY   ",
      "    YY~~~~~YY   ",
      "    YY~~~~~YY   ",
      "    YY~~~~~YY   ",
      "YYYYYY~~~~~YYYYY",
      "YYYYYY~~~~~YYYYY",
      "~~~~~~~~~~~~~~~~",
      "~~~~~~~~~~~~~~~~",
      "~~~~~~~~~~~~~~~~",
      "~~~~~~~~~~~~~~~~",
      "~~~~~~~~~~~~~~~~",
      "YYYYYY~~~~~YYYYY",
      "YYYYYY~~~~~YYYYY",
      "    YY~~~~~YY   ",
      "    YY~~~~~YY   ",
      "    YY~~~~~YY   "
    ],
    [
      "      YYYYY     ",
      "      YYYYY     ",
      "      YYYYY     ",
      "      YYYYY     ",
      "      YYYYY     ",
      "      YYYYY     ",
      "YYYYYYYYYYYYYYYY",
      "YYYYYYYYYYYYYYYY",
      "YYYYYYYYYYYYYYYY",
      "YYYYYYYYYYYYYYYY",
      "YYYYYYYYYYYYYYYY",
      "      YYYYY     ",
      "      YYYYY     ",
      "      YYYYY     ",
      "      YYYYY     ",
      "      YYYYY     "
    ]
  ]
}