{
  "xsize": 16,
  "zsize": 16,
  "refpalette": "oilrig",
  "slices": [
    [
      "                ",
      "                ",
      "                ",
      "                ",
      "                ",
      "                ",
      "                ",
      "                ",
      "                ",
      "                ",
      "                ",
      "                ",
      " xxx            ",
      " xxx            ",
      " xxx            ",
      "                "
    ],
    [
      "xxxxxxxxxxxxxxxx",
      "xxxxxxxxxxxxxxxx",
      "xxxxxxxxxxxxxxxx",
      "xxxxxxxxxxxxxxxx",
      "xxxxxxxxxxxxxxxx",
      "xxxxxxxxxxxxxxxx",
      "xxxxxxxxxxxxxxxx",
      "xxxxxxxxxxxxxxxx",
      "xxxxxxxxxxxxxxxx",
      "xxxxxxxxxxxxxxxx",
      "xxxxxxxxxxxxxxxx",
      "xxxxxxxxxxxxxxxx",
      "xxxxxxxxxxxxxxxx",
      "xxxxxxxxxxxxxxxx",
      "xxxxxxxxxxxxxxxx",
      "xxxxxxxxxxxxxxxx"
    ],
    [
      " D              ",
      " D              ",
      " Dj             ",
      " D     m        ",
      " uDDDDDnD::D    ",
      ":D     m   D    ",
      ":D         Ds   ",
      " D         DE   ",
      ":D      EE Ds   ",
      ":D      EE D    ",
      " DC        D    ",
      "iD        ND    ",
      "iD         D    ",
      " D         D    ",
      " uDDDDDDDDDuDDDD",
      "   ll :: ::     "
    ],
    [
      " D              ",
      " D              ",
      " Dj             ",
      " D              ",
      " uDDDDDOD::D    ",
      ":w         D    ",
      ":w         D    ",
      " D         DP   ",
      ":w      PP D    ",
      ":w      PP D    ",
      " D         D    ",
      " w        ND    ",
      " w         D    ",
      " D        1D    ",
      " uDwwDwwDwwuDDDD",
      "      :: ::     "
    ],
    [
      " D              ",
      " D              ",
      " Dj             ",
      " D              ",
      " uDDDDDDD::D    ",
      ":D         D    ",
      ":D         D    ",
      " D         D    ",
      ":D         D    ",
      ":D         D    ",
      " D         D    ",
      "6D         D    ",
      "6D         D    ",
      " D         D    ",
      " uDDDDDDDDDuDDDD",
      "   55 :: ::     "
    ],
    [
      "xxxxxxxxxxxxxxxx",
      "xxxxxxxxxxxxxxxx",
      "xxjxxxxxxxxxxxxx",
      "xxxxxxxxxxxxxxxx",
      "xxxxxxxxxxxxxxxx",
      "xxxxxxxxxxxxxxxx",
      "xxxxxxxxxxxxxxxx",
      "xxxxxxxxxxxxxxxx",
      "xxxxxxxxxxxxxxxx",
      "xxxxxxxxxxxxxxxx",
      "xxxxxxxxxxxxxxxx",
      "xxxxxxxxxxxxxxxx",
      "xxxxxxxxxxxxxxxx",
      "xxxxxxxxxxxxxxxx",
      "xxxxxxxxxxxxxxxx",
      "xxxxxxxxxxxxxxxx"
    ],
    [
      "                ",
      " ::::           ",
      " :Vm            ",
      " ::::           ",
      " =======        ",
      "       =        ",
      "       2        ",
      "       =        ",
      " =======        ",
      "                ",
      "                ",
      "                ",
      " u3u u3u u3u    ",
      " 3 3 3 3 3 3    ",
      " u3u u3u u3u    ",
      "                "
    ],
    [
      "                ",
      "                ",
      "                ",
      "                ",
      "                ",
      "                ",
      "       2        ",
      "                ",
      "                ",
      "                ",
      "                ",
      "                ",
      " u2u u2u u2u    ",
      " 2 2 2 2 2 2    ",
      " u2u u2u u2u    ",
      "                "
    ],
    [
      "                ",
      "                ",
      "                ",
      "                ",
      "                ",
      "                ",
      "       2        ",
      "                ",
      "                ",
      "                ",
      "                ",
      "                ",
      " === === ===    ",
      " === === ===    ",
      " === === ===    ",
      "                "
    ],
    [
      "                ",
      "                ",
      "                ",
      "                ",
      "                ",
      "      ^^^       ",
      "  3   ^2^       ",
      "      ^^^       ",
      "                ",
      "                ",
      "                ",
      "                ",
      "                ",
      "                ",
      "                ",
      "                "
    ],
    [
      "                ",
      "                ",
      "                ",
      "                ",
      "                ",
      "      w&w       ",
      "  :   & &       ",
      "      w&w       ",
      "                ",
      "                ",
      "                ",
      "                ",
      "                ",
      "                ",
      "                ",
      "                "
    ],
    [
      "                ",
      "                ",
      "                ",
      "                ",
      "                ",
      "      ===       ",
      "  :   =2=       ",
      "      ===       ",
      "                ",
      "                ",
      "                ",
      "                ",
      "                ",
      "                ",
      "                ",
      "                "
    ],
    [
      "                ",
      "                ",
      "                ",
      "                ",
      "                ",
      "                ",
      "  :::::2|       ",
      "                ",
      "                ",
      "                ",
      "                ",
      "                ",
      "                ",
      "                ",
      "                ",
      "                "
    ],
    [
      "                ",
      "                ",
      "                ",
      "                ",
      "                ",
      "                ",
      "                ",
      "                ",
      "                ",
      "                ",
      "                ",
      "                ",
      "                ",
      "                ",
      "                ",
      "                "
    ],
    [
      "                ",
      "                ",
      "                ",
      "                ",
      "                ",
      "                ",
      "                ",
      "                ",
      "                ",
      "                ",
      "                ",
      "                ",
      "                ",
      "                ",
      "                ",
      "                "
    ],
    [
      "                ",
      "                ",
      "                ",
      "                ",
      "                ",
      "                ",
      "                ",
      "                ",
      "                ",
      "                ",
      "                ",
      "                ",
      "                ",
      "                ",
      "                ",
      "                "
    ],
    [
      "                ",
      "                ",
      "                ",
      "                ",
      "                ",
      "                ",
      "                ",
      "                ",
      "                ",
      "                ",
      "                ",
      "                ",
      "                ",
      "                ",
      "                ",
      "                "
    ],
    [
      "                ",
      "                ",
      "                ",
      "                ",
      "                ",
      "                ",
      "                ",
      "                ",
      "                ",
      "                ",
      "                ",
      "                ",
      "                ",
      "                ",
      "                ",
      "                "
    ],
    [
      "                ",
      "                ",
      "                ",
      "                ",
      "                ",
      "                ",
      "                ",
      "                ",
      "                ",
      "                ",
      "                ",
      "                ",
      "                ",
      "                ",
      "                ",
      "                "
    ],
    [
      "                ",
      "                ",
      "                ",
      "                ",
      "                ",
      "                ",
      "                ",
      "                ",
      "                ",
      "                ",
      "                ",
      "                ",
      "                ",
      "                ",
      "                ",
      "                "
    ],
    [
      "                ",
      "                ",
      "                ",
      "                ",
      "                ",
      "                ",
      "                ",
      "                ",
      "                ",
      "                ",
      "                ",
      "                ",
      "                ",
      "                ",
      "                ",
      "                "
    ],
    [
      "                ",
      "                ",
      "                ",
      "                ",
      "                ",
      "                ",
      "                ",
      "                ",
      "                ",
      "                ",
      "                ",
      "                ",
      "                ",
      "                ",
      "                ",
      "                "
    ]
  ]
}
