{
  "xsize": 16,
  "zsize": 16,
  "refpalette": "oilrig",
  "slices": [
    [
      "                ",
      "            xxx ",
      "            xxx ",
      "            xxx ",
      "                ",
      "                ",
      "                ",
      "                ",
      "                ",
      "                ",
      "                ",
      "                ",
      "                ",
      "                ",
      "                ",
      "                "
    ],
    [
      "                ",
      "            xxx ",
      "            xxx ",
      "            xxx ",
      "                ",
      "                ",
      "                ",
      "                ",
      "                ",
      "                ",
      "                ",
      "                ",
      "                ",
      "                ",
      "                ",
      "                "
    ],
    [
      "                ",
      "            xxx ",
      "            xxx ",
      "            xxx ",
      "                ",
      "                ",
      "                ",
      "                ",
      "                ",
      "                ",
      "                ",
      "                ",
      "                ",
      "                ",
      "                ",
      "                "
    ],
    [
      "                ",
      "            xxx ",
      "            xxx ",
      "            xxx ",
      "                ",
      "                ",
      "                ",
      "                ",
      "                ",
      "                ",
      "                ",
      "                ",
      "                ",
      "                ",
      "                ",
      "                "
    ],
    [
      "                ",
      "            xxx ",
      "            xxx ",
      "            xxx ",
      "                ",
      "                ",
      "                ",
      "                ",
      "                ",
      "                ",
      "                ",
      "                ",
      "                ",
      "                ",
      "                ",
      "                "
    ],
    [
      "                ",
      "            xxx ",
      "            xxx ",
      "            xxx ",
      "                ",
      "                ",
      "                ",
      "                ",
      "                ",
      "                ",
      "                ",
      "                ",
      "                ",
      "                ",
      "                ",
      "                "
    ],
    [
      "                ",
      "            xxx ",
      "            xxx ",
      "            xxx ",
      "                ",
      "                ",
      "                ",
      "                ",
      "                ",
      "                ",
      "                ",
      "                ",
      "                ",
      "                ",
      "                ",
      "                "
    ],
    [
      "                ",
      "            xxx ",
      "            xxx ",
      "            xxx ",
      "                ",
      "                ",
      "                ",
      "                ",
      "                ",
      "                ",
      "                ",
      "                ",
      "                ",
      "                ",
      "                ",
      "                "
    ],
    [
      "                ",
      "            xxx ",
      "            xxx ",
      "            xxx ",
      "                ",
      "                ",
      "                ",
      "                ",
      "                ",
      "                ",
      "                ",
      "                ",
      "                ",
      "                ",
      "                ",
      "                "
    ],
    [
      "                ",
      "            xxx ",
      "            xxx ",
      "            xxx ",
      "                ",
      "                ",
      "                ",
      "                ",
      "                ",
      "                ",
      "                ",
      "                ",
      "                ",
      "                ",
      "                ",
      "                "
    ],
    [
      "                ",
      "            xxx ",
      "            xxx ",
      "            xxx ",
      "                ",
      "                ",
      "                ",
      "                ",
      "                ",
      "                ",
      "                ",
      "                ",
      "                ",
      "                ",
      "                ",
      "                "
    ],
    [
      "                ",
      "            xxx ",
      "            xxx ",
      "            xxx ",
      "                ",
      "                ",
      "                ",
      "                ",
      "                ",
      "                ",
      "                ",
      "                ",
      "                ",
      "                ",
      "                ",
      "                "
    ],
    [
      "                ",
      "            xxx ",
      "            xxx ",
      "            xxx ",
      "                ",
      "                ",
      "                ",
      "                ",
      "                ",
      "                ",
      "                ",
      "                ",
      "                ",
      "                ",
      "                ",
      "                "
    ],
    [
      "                ",
      "            xxx ",
      "            xxx ",
      "            xxx ",
      "                ",
      "                ",
      "                ",
      "                ",
      "                ",
      "                ",
      "                ",
      "                ",
      "                ",
      "                ",
      "                ",
      "                "
    ],
    [
      "xxxxxxxxxxxxxxxx",
      "xxxxxxxxxxxxxxxx",
      "xxxxxxxxxxxxxxxx",
      "xxxxxxxxxxxxxxxx",
      "xxxxxxxxxxxxxxxx",
      "xxxxxxxxxxxxxxxx",
      "xxxxxxxxxxxxxxxx",
      "xxxxxxxxxxxxxxxx",
      "xxxxxxxxxxxxxxxx",
      "xxxxxxxxxxxxxxxx",
      "xxxxxxxxxxxxxxxx",
      "xxxxxxxxxxxxxxxx",
      "xxxxxxxxxxxxxxxx",
      "xxxxxxxxxxxxxxxx",
      "xxxxxxxxxxxxxxxx",
      "xxxxxxxxxxxxxxxx"
    ],
    [
      "     :: :: oo   ",
      "DDDDuDDDDDDDDDu ",
      "              D ",
      "              Dp",
      "              Dp",
      "              D ",
      "              D:",
      "              D:",
      "              D ",
      "              D:",
      "              D:",
      "              u ",
      "              D ",
      "              D ",
      "              D ",
      "              D "
    ],
    [
      "     :: :: oo   ",
      "DDDDuDDDDDDDDDu ",
      "              D ",
      "              w ",
      "              w ",
      "              D ",
      "              w:",
      "              w:",
      "              D ",
      "              w:",
      "              w:",
      "              u ",
      "              D ",
      "              D ",
      "              D ",
      "              D "
    ],
    [
      "     :: :: 77   ",
      "DDDDuDDDDDDDDDu ",
      "              D ",
      "              D8",
      "              D8",
      "              D ",
      "              D:",
      "              D:",
      "              D ",
      "              D:",
      "              D:",
      "              u ",
      "              D ",
      "              D ",
      "              D ",
      "              D "
    ],
    [
      "xxxxxxxxxxxxxxxx",
      "xxxxxxxxxxxxxxxx",
      "xxxxxxxxxxxxxxxx",
      "xxxxxxxxxxxxxxxx",
      "xxxxxxxxxxxxxxxx",
      "xxxxxxxxxxxxxxxx",
      "xxxxxxxxxxxxxxxx",
      "xxxxxxxxxxxxxxxx",
      "xxxxxxxxxxxxxxxx",
      "xxxxxxxxxxxxxxxx",
      "xxxxxxxxxxxxxxxx",
      "xxxxxxxxxxxxxxxx",
      "xxxxxxxxxxxxxxxx",
      "xxxxxxxxxxxxxxxx",
      "xxxxxxxxxxxxxxxx",
      "xxxxxxxxxxxxxxxx"
    ]
  ]
}