{
  "xsize": 16,
  "zsize": 16,
  "refpalette": "rails",
  "slices": [
    [
      "      yyyyy     ",
      "      yyyyy     ",
      "      yyyyy     ",
      "      yyyyy     ",
      "      yyyyy     ",
      "      yyyyy     ",
      "      yyyyy     ",
      "      yyyyy     ",
      "      yyyyy     ",
      "      yyyyy     ",
      "      yyyyy     ",
      "      yyyyy     ",
      "      yyyyy     ",
      "      yyyyy     ",
      "      yyyyy     ",
      "      yyyyy     "
    ],
    [
      "      yykyy     ",
      "      yykyy     ",
      "      yykyy     ",
      "      yykyy     ",
      "      yykyy     ",
      "      yykyy     ",
      "      yykyy     ",
      "      yykyy     ",
      "      ygmgy     ",
      "      yykyy     ",
      "      yykyy     ",
      "      yykyy     ",
      "      yykyy     ",
      "      yykyy     ",
      "      yykyy     ",
      "      yykyy     "
    ],
    [
      "      y~~~y     ",
      "      y~~~y     ",
      "      y~~~y     ",
      "      y~~~y     ",
      "      y~~~y     ",
      "      y~~~y     ",
      "      yT~~y     ",
      "      y~~~y     ",
      "      y~~~y     ",
      "      y~~~y     ",
      "      y~~~y     ",
      "      y~~~y     ",
      "      y~~~y     ",
      "      y~~~y     ",
      "      y~~~y     ",
      "      y~~~y     "
    ],
    [
      "      +~~~+     ",
      "      +~~~+     ",
      "      +~~~+     ",
      "      +~~~+     ",
      "      +~~~+     ",
      "      +~~~+     ",
      "      +~~~+     ",
      "      +~~~+     ",
      "      +~~~+     ",
      "      +~~~+     ",
      "      +~~~+     ",
      "      +~~~+     ",
      "      +~~~+     ",
      "      +~~~+     ",
      "      +~~~+     ",
      "      +~~~+     "
    ],
    [
      "      +~~~+     ",
      "      +~~~+     ",
      "      +~~~+     ",
      "      +~~~+     ",
      "      +~~~+     ",
      "      +~~~+     ",
      "      +~~~+     ",
      "      +~~~+     ",
      "      +~~~+     ",
      "      +~~~+     ",
      "      +~~~+     ",
      "      +~~~+     ",
      "      +~~~+     ",
      "      +~~~+     ",
      "      +~~~+     ",
      "      +~~~+     "
    ],
    [
      "      yy+yy     ",
      "      yy+yy     ",
      "      yy+yy     ",
      "      yy+yy     ",
      "      yy+yy     ",
      "      yy+yy     ",
      "      yy+yy     ",
      "      yy+yy     ",
      "      yy+yy     ",
      "      yy+yy     ",
      "      yy+yy     ",
      "      yy+yy     ",
      "      yy+yy     ",
      "      yy+yy     ",
      "      yy+yy     ",
      "      yy+yy     "
    ]
  ]
}