{
  "xsize": 16,
  "zsize": 16,
  "refpalette": "rails",
  "slices": [
    [
      "      yyyyy     ",
      "      yyyyy     ",
      "      yyyyy     ",
      "yyyyyyyyyyy     ",
      "yyyyyyyyyyy     ",
      "yyyyyyyyyyy     ",
      "yyyyyyyyyyy     ",
      "yyyyyyyyyyy     ",
      "yyyyyyyyyyy     ",
      "yyyyyyyyyyy     ",
      "yyyyyyyyyyy     ",
      "yyyyyyyyyyy     ",
      "      yyyyy     ",
      "      yyyyy     ",
      "      yyyyy     ",
      "      yyyyy     "
    ],
    [
      "      yykyy     ",
      "      yykyy     ",
      "      yykyy     ",
      "yyyyyyyykyy     ",
      "yyyyyyygmyy     ",
      "eeeeeeefryy     ",
      "yyyyyyyyyyy     ",
      "yyyyyyyyyyy     ",
      "yyyyyyyyyyy     ",
      "eeeeeeefsyy     ",
      "yyyyyyygmyy     ",
      "yyyyyyyykyy     ",
      "      yykyy     ",
      "      yykyy     ",
      "      yykyy     ",
      "      yykyy     "
    ],
    [
      "      y~~~y     ",
      "      y~~~y     ",
      "      y~~~y     ",
      "yyyyyyy~~~y     ",
      "~~~~~~~~~~y     ",
      "~~~~~~~~~~y     ",
      "~~~~~~~~~~y     ",
      "~~~~~~~~yyy     ",
      "~~~~~~~~~~y     ",
      "~~~~~~~~~~y     ",
      "~~~~~~~~~~y     ",
      "yyyyyyy~~~y     ",
      "      y~~~y     ",
      "      y~~~y     ",
      "      y~~~y     ",
      "      y~~~y     "
    ],
    [
      "      y~~~y     ",
      "      y~~~y     ",
      "      y~~~y     ",
      "yyyyyyy~~~y     ",
      "~~~~~~~~~~y     ",
      "~~~~~~~~~~y     ",
      "~~~~~~~~~~y     ",
      "~~~~~~~~yyy     ",
      "~~~~~~~~~~y     ",
      "~~~~~~~~~~y     ",
      "~~~~~~~~~~y     ",
      "yyyyyyy~~~y     ",
      "      y~~~y     ",
      "      y~~~y     ",
      "      y~~~y     ",
      "      y~~~y     "
    ],
    [
      "      y~~~y     ",
      "      y~~~y     ",
      "      y~~~y     ",
      "yyyyyyy~~~y     ",
      "~~~~~~~~~~y     ",
      "~~~~~~~~~~y     ",
      "~~~~~~~~~~y     ",
      "~~~~~~~~yyy     ",
      "~~~~~~~~~~y     ",
      "~~~~~~~~~~y     ",
      "~~~~~~~~~~y     ",
      "yyyyyyy~~~y     ",
      "      y~~~y     ",
      "      y~~~y     ",
      "      y~~~y     ",
      "      y~~~y     "
    ],
    [
      "      yyyyy     ",
      "      yyyyy     ",
      "      yyyyy     ",
      "yyyyyyyyyyy     ",
      "yyyyyyyyyyy     ",
      "yyyyyyyyyyy     ",
      "yyyyyyyyyyy     ",
      "yyyyyyyyyyy     ",
      "yyyyyyyyyyy     ",
      "yyyyyyyyyyy     ",
      "yyyyyyyyyyy     ",
      "yyyyyyyyyyy     ",
      "      yyyyy     ",
      "      yyyyy     ",
      "      yyyyy     ",
      "      yyyyy     "
    ]
  ]
}