{
  "xsize": 16,
  "zsize": 16,
  "refpalette": "rails",
  "slices": [
    [
      "yyyyyyyyyyyyyyyy",
      "yyyyyyyyyyyyyyyy",
      "yyyyyyyyyyyyyyyy",
      "yyyyyyyyyyyyyyyy",
      "yyyyyyyyyyyyyyyy",
      "yyyyyyyyyyyyyyyy",
      "yyyyyyyyyyyyyyyy",
      "yyyyyyyyyyyyyyyy",
      "yyyyyyyyyyyyyyyy",
      "yyyyyyyyyyyyyyyy",
      "yyyyyyyyyyyyyyyy",
      "yyyyyyyyyyyyyyyy",
      "yyyyyyyyyyyyyyyy",
      "yyyyyyyyyyyyyyyy",
      "yyyyyyyyyyyyyyyy",
      "yyyyyyyyyyyyyyyy"
    ],
    [
      "yyyyyyyyyyyyyyyy",
      "yyyyyyyyyyyyyyyy",
      "yyyyyyyyyyyyyyyy",
      "yyyyyyyyyyyyyyyy",
      "yyyyyyyyyyyyyyyy",
      "yyyyyyyyyyyyyyyy",
      "yyyyyyyyyyyyyyyy",
      "yyyyyyyyyyyyyyyy",
      "yyyyyyyyyyyyyyyy",
      "yyyyyyyyyyyyyyyy",
      "yyyyyyyyyyyyyyyy",
      "yyyyyyyyyyyyyyyy",
      "yyyyyyyyyyyyyyyy",
      "yyyyyyyyyyyyyyyy",
      "yyyyyyyyyyyyyyyy",
      "yyyyyyyyyyyyyyyy"
    ],
    [
      "yyyyyy~~yyyyyyyy",
      "yyy~~~~~y~~~~yyy",
      "yyy~~~~~y~~~~yyy",
      "yyy~~~~~~~~~~yyy",
      "yyy~~~~~y~~~~yyy",
      "yyy~~~~~y~~~~yyy",
      "yyy~~~~~y~~~~yyy",
      "yyy~~~~~y1~~~yyy",
      "yyy~~~~~y!~~~yyy",
      "yyy~~~~~y!~~1yyy",
      "yyy~~~~~y!~~~yyy",
      "yyy~~~~~y1~~~yyy",
      "yyy~~~~~y~~~~yyy",
      "yyy~~~~~y~~~~yyy",
      "yyy~~~~~y~~~~yyy",
      "yyyyyy~~yyyyyyyy"
    ],
    [
      "yyyyyy~~yyyyyyyy",
      "yyy~~~~~y~~~~yyy",
      "yyy~~~~~y~~~~yyy",
      "yyy~~~~~~~~~~yyy",
      "yyy~~~~~y~~~~yyy",
      "yyy~~~~~y~~~~yyy",
      "yyyF~~~~y~~~~yyy",
      "yyyF~~~~y~~~~yyy",
      "yyy~~~~~y~~~~yyy",
      "yyy~~~~~y~~~~yyy",
      "yyy~~~~~y~~~~yyy",
      "yyy~~~~~y~~~~yyy",
      "yyy~~~~~y~~~~yyy",
      "yyy~~~~~y~~~~yyy",
      "yyy~~~~~y~~~~yyy",
      "yyyyyy~~yyyyyyyy"
    ],
    [
      "yyyyyyyyyyyyyyyy",
      "yyy~~~~~y~~~~yyy",
      "yyy~~~~~y~~~~yyy",
      "yyy~~~~~y~~~~yyy",
      "yyy~~~~~y~~~~yyy",
      "yyy~~~~~y~~~~yyy",
      "yyy~~~~~y~~~~yyy",
      "yyy~~~~~y~~~~yyy",
      "yyy~~~~~y~~~~yyy",
      "yyy~~~~~y~~~~yyy",
      "yyy~~~~~y~~~~yyy",
      "yyy~~~~~y~~~~yyy",
      "yyy~~~~~y~~~~yyy",
      "yyy~~~~~y~~~~yyy",
      "yyy~~~~~y~~~~yyy",
      "yyyyyyyyyyyyyyyy"
    ],
    [
      "yyyyyyyyyyyyyyyy",
      "yyyyyyyyyyyyyyyy",
      "yyyyyyyyyyyyyyyy",
      "yyyyyyyyyyyyyyyy",
      "yyyyyyyyyyyyyyyy",
      "yyyyyyyyyyyyyyyy",
      "yyyyyyyyyyyyyyyy",
      "yyyyyyyyyyyyyyyy",
      "yyyyyyyyyyyyyyyy",
      "yyyyyyyyyyyyyyyy",
      "yyyyyyyyyyyyyyyy",
      "yyyyyyyyyyyyyyyy",
      "yyyyyyyyyyyyyyyy",
      "yyyyyyyyyyyyyyyy",
      "yyyyyyyyyyyyyyyy",
      "yyyyyyyyyyyyyyyy"
    ]
  ]
}