{
  "xsize": 16,
  "zsize": 16,
  "refpalette": "rails",
  "slices": [
    [
      "y              y",
      "y              y",
      "y              y",
      "yyyyyyyyyyyyyyyy",
      "yyyyyyyyyyyyyyyy",
      "yyyyyyyyyyyyyyyy",
      "yyyyyyyyyyyyyyyy",
      "yyyyyyyyyyyyyyyy",
      "yyyyyyyyyyyyyyyy",
      "yyyyyyyyyyyyyyyy",
      "yyyyyyyyyyyyyyyy",
      "yyyyyyyyyyyyyyyy",
      "y              y",
      "y              y",
      "y              y",
      "y               "
    ],
    [
      "y              y",
      "y              y",
      "y              y",
      "yyyyyyyyyyyyyyyy",
      "yyyyyyyyyyyyyyyy",
      "eeeeeeefeeeeeeee",
      "yyyyyyygyyyyyyyy",
      "eeeeeeefeeeeeeee",
      "yyyyyyygyyyyyyyy",
      "eeeeeeefeeeeeeee",
      "yyyyyyyyyyyyyyyy",
      "yyyyyyyyyyyyyyyy",
      "y              y",
      "y              y",
      "y              y",
      "y               "
    ],
    [
      "y              y",
      "y              y",
      "y              y",
      "yyyyyyyyyyyyyyyy",
      "~~~~~~~~~~~~~~~~",
      "~~~~~~~~~~~~~~~~",
      "~~~~~~~~~~~~~~~~",
      "~~~~~~~~~~~~~~~~",
      "~~~~~~~~~~~~~~~~",
      "~~~~~~~~~~~~~~~~",
      "~~~~~~~~~~~~~~~~",
      "yyyyyyyyyyyyyyyy",
      "y              y",
      "y              y",
      "y              y",
      "y               "
    ],
    [
      "y              y",
      "y              y",
      "y              y",
      "yyyyyyyyyyyyyyyy",
      "~~~~~~~~~~~~~~~~",
      "~~~~~~~~~~~~~~~~",
      "~~~~~~~~~~~~~~~~",
      "~~~~~~~~~~~~~~~~",
      "~~~~~~~~~~~~~~~~",
      "~~~~~~~~~~~~~~~~",
      "~~~~~~~~~~~~~~~~",
      "yyyyyyyyyyyyyyyy",
      "y              y",
      "y              y",
      "y              y",
      "y               "
    ],
    [
      "y              y",
      "y              y",
      "y              y",
      "yyyyyyyyyyyyyyyy",
      "~~~~~~~~T~~~~~~~",
      "~~~~~~~~~~~~~~~~",
      "~~~~~~~~~~~~~~~~",
      "~~~~~~~~~~~~~~~~",
      "~~~~~~~~~~~~~~~~",
      "~~~~~~~~~~~~~~~~",
      "~~~~~~~~~~~~~~~~",
      "yyyyyyyyyyyyyyyy",
      "y              y",
      "y              y",
      "y              y",
      "y               "
    ],
    [
      "y              y",
      "y              y",
      "y              y",
      "yyyyyyyyyyyyyyyy",
      "yyyyyyyyyyyyyyyy",
      "yyyyyyyyyyyyyyyy",
      "yyyyyyyyyyyyyyyy",
      "yyyyyyyyyyyyyyyy",
      "yyyyyyyyyyyyyyyy",
      "yyyyyyyyyyyyyyyy",
      "yyyyyyyyyyyyyyyy",
      "yyyyyyyyyyyyyyyy",
      "y              y",
      "y              y",
      "y              y",
      "y               "
    ]
  ]
}