{
  "xsize": 16,
  "zsize": 16,
  "refpalette": "rails",
  "slices": [
    [
      "      yyyyy     ",
      "      yyyyy     ",
      "      yyyyy     ",
      "yyyyyyyyyyyyyyyy",
      "yyyyyyyyyyyyyyyy",
      "yyyyyyyyyyyyyyyy",
      "yyyyyyyyyyyyyyyy",
      "yyyyyyyyyyyyyyyy",
      "yyyyyyyyyyyyyyyy",
      "yyyyyyyyyyyyyyyy",
      "yyyyyyyyyyyyyyyy",
      "yyyyyyyyyyyyyyyy",
      "      yyyyy     ",
      "      yyyyy     ",
      "      yyyyy     ",
      "      yyyyy     "
    ],
    [
      "      yykyy     ",
      "      ygmgy     ",
      "      yykyy     ",
      "yyyyyyyykyyyyyyy",
      "yyyyyyyykyyyyyyy",
      "yyyyyyyynfeeeeee",
      "ygyyyyyyygyyyyyy",
      "efeeeeeeefeeeeee",
      "ygyyyyyyygyyyyyy",
      "yyyyyyyyqfeeeeee",
      "yyyyyyyykyyyyyyy",
      "yyyyyyyykyyyyyyy",
      "      yykyy     ",
      "      yykyy     ",
      "      ygmgy     ",
      "      yykyy     "
    ],
    [
      "      y~~~y     ",
      "      y~~~y     ",
      "      y~~~y     ",
      "yyyyyyy~~~yyyyyy",
      "~~~~~~~~~~~~~~~~",
      "~~~~~~~~~~~~~~~~",
      "~~~~~~~~~~~~~~~~",
      "~~~~~~~~~~~~~~~~",
      "~~~~~~~~~~~~~~~~",
      "~~~~~~~~~~~~~~~~",
      "~~~~~~~~~~~~~~~~",
      "yyyyyyy~~~yyyyyy",
      "      y~~~y     ",
      "      y~~~y     ",
      "      y~~~y     ",
      "      y~~~y     "
    ],
    [
      "      y~~~y     ",
      "      y~~~y     ",
      "      y~~~y     ",
      "yyyyyyy~~~yyyyyy",
      "~~~~~~~~~~~~~~~~",
      "~~~~~~~~~~~~~~~~",
      "~~~~~~~~~~~~~~~~",
      "~~~~~~~~~~~~~~~~",
      "~~~~~~~~~~~~~~~~",
      "~~~~~~~~~~~~~~~~",
      "~~~~~~~~~~~~~~~~",
      "yyyyyyy~~~yyyyyy",
      "      y~~~y     ",
      "      y~~~y     ",
      "      y~~~y     ",
      "      y~~~y     "
    ],
    [
      "      y~~~y     ",
      "      y~~~y     ",
      "      y~~~y     ",
      "yyyyyyy~~~yyyyyy",
      "~~~T~~~~~~~~~~~~",
      "~~~~~~~~~~~~~~~~",
      "~~~~~~~~~~~~~~~~",
      "~~~~~~~~~~~~~~~~",
      "~~~~~~~~~~~~~~~~",
      "~~~~~~~~~~~~~~~~",
      "~~~~~~~~~~~~~T~~",
      "yyyyyyy~~~yyyyyy",
      "      y~~~y     ",
      "      y~~~y     ",
      "      y~~~y     ",
      "      y~~~y     "
    ],
    [
      "      yyyyy     ",
      "      yyyyy     ",
      "      yyyyy     ",
      "yyyyyyyyyyyyyyyy",
      "yyyyyyyyyyyyyyyy",
      "yyyyyyyyyyyyyyyy",
      "yyyyyyyyyyyyyyyy",
      "yyyyyyyyyyyyyyyy",
      "yyyyyyyyyyyyyyyy",
      "yyyyyyyyyyyyyyyy",
      "yyyyyyyyyyyyyyyy",
      "yyyyyyyyyyyyyyyy",
      "      yyyyy     ",
      "      yyyyy     ",
      "      yyyyy     ",
      "      yyyyy     "
    ]
  ]
}