{
  "xsize": 16,
  "zsize": 16,
  "refpalette": "rails",
  "slices": [
    [
      "y              y",
      "y              y",
      "y              y",
      "yyyyyyyyyyyyyyyy",
      "yyyyyyyyyyyyyyyy",
      "yyyyyyyyyyyyyyyy",
      "yyyyyyyyyyyyyyyy",
      "yyyyyyyyyyyyyyyy",
      "yyyyyyyyyyyyyyyy",
      "yyyyyyyyyyyyyyyy",
      "yyyyyyyyyyyyyyyy",
      "yyyyyyyyyyyyyyyy",
      "y              y",
      "y              y",
      "y              y",
      "y               "
    ],
    [
      "y              y",
      "y              y",
      "y              y",
      "yyyyyyyyyyyyyyyy",
      "yyyyyyyyyyyyyyyy",
      "eeeeeeefeeeyyyye",
      "yyyyyyygyyyyyyyy",
      "eeeeeeefeeeyyyye",
      "yyyyyyygyyyyyyyy",
      "eeeeeeefeeeyyyye",
      "yyyyyyyyyyyyyyyy",
      "yyyyyyyyyyyyyyyy",
      "y              y",
      "y              y",
      "y              y",
      "y               "
    ],
    [
      "y              y",
      "y              y",
      "y              y",
      "yyyyyyyyyyyyyyyy",
      "~~~~~~~~~~~~~~~y",
      "~~~~~~~~~~~~~~~y",
      "~~~~~~~~~~~~~~~y",
      "~~~~~~~~~~~~~~~y",
      "~~~~~~~~~~~~~~~y",
      "~~~~~~~~~~~~~~~y",
      "~~~~~~~~~~~~~~~y",
      "yyyyyyyyyyyyyyyy",
      "y              y",
      "y              y",
      "y              y",
      "y               "
    ],
    [
      "y              y",
      "y              y",
      "y              y",
      "yyyyyyyyyyyyyyyy",
      "~~~~~~~~~~~~~~~y",
      "~~~~~~~~~~~~~~~y",
      "~~~~~~~~~~~~~~~y",
      "~~~~~~~~~~~~~~~y",
      "~~~~~~~~~~~~~~~y",
      "~~~~~~~~~~~~~~~y",
      "~~~~~~~~~~~~~~~y",
      "yyyyyyyyyyyyyyyy",
      "y              y",
      "y              y",
      "y              y",
      "y               "
    ],
    [
      "y              y",
      "y              y",
      "y              y",
      "yyyyyyyyyyyyyyyy",
      "~~~~~~~~T~~~~~~y",
      "~~~~~~~~~~~~~~~y",
      "~~~~~~~~~~~~~~~y",
      "~~~~~~~~~~~~~~~y",
      "~~~~~~~~~~~~~~~y",
      "~~~~~~~~~~~~~~~y",
      "~~~~~~~~~~~~~~~y",
      "yyyyyyyyyyyyyyyy",
      "y              y",
      "y              y",
      "y              y",
      "y               "
    ],
    [
      "y              y",
      "y              y",
      "y              y",
      "yyyyyyyyyyyyyyyy",
      "yyyyyyyyyyyyyyyy",
      "yyyyyyyyyyyyyyyy",
      "yyyyyyyyyyyyyyyy",
      "yyyyyyyyyyyyyyyy",
      "yyyyyyyyyyyyyyyy",
      "yyyyyyyyyyyyyyyy",
      "yyyyyyyyyyyyyyyy",
      "yyyyyyyyyyyyyyyy",
      "y              y",
      "y              y",
      "y              y",
      "y               "
    ]
  ]
}