{
  "xsize": 16,
  "zsize": 16,
  "refpalette": "rails",
  "slices": [
    [
      "yyyyyyyyyyyyyyyy",
      "yyyyyyyyyyyyyyyy",
      "yyyyyyyyyyyyyyyy",
      "yyyyyyyyyyyyyyyy",
      "yyyyyyyyyyyyyyyy",
      "yyyyyyyyyyyyyyyy",
      "yyyyyyyyyyyyyyyy",
      "yyyyyyyyyyyyyyyy",
      "yyyyyyyyyyyyyyyy",
      "yyyyyyyyyyyyyyyy",
      "yyyyyyyyyyyyyyyy",
      "yyyyyyyyyyyyyyyy",
      "yyyyyyyyyyyyyyyy",
      "yyyyyyyyyyyyyyyy",
      "yyyyyyyyyyyyyyyy",
      "yyyyyyyyyyyyyyyy"
    ],
    [
      "yyyyyyyyyyyyyyyy",
      "yyyyyyyyyyyyyyyy",
      "y4yyyyyyyyyyyy1y",
      "yyyyyyyyyyyyyyyy",
      "yyyyyyyyyyyyyyyy",
      "yyyyyyyyyyyyyyyy",
      "yyyyyyyyyyyyyyyy",
      "yyyyyyyyyyyyyyyy",
      "y4yyyyyyyyyyyyyy",
      "yyyyyyyyyyyyyyyy",
      "yyyyyyyyyyyyyyyy",
      "yyyyyyyyyyyyyyyy",
      "yyyyyyyyyyyyyyyy",
      "y1yyyyyyyyyyyy1y",
      "yyyyyyyyyyyyyyyy",
      "yyyyyyyyyyyyyyyy"
    ],
    [
      "yyyyyy~~yyyyyyyy",
      "yyy~~~~~~~~~~yyy",
      "yyy~~~~~~~~~~yyy",
      "yyy~~~~~~~~~~yyy",
      "yyyC~~~~~yyyyyyy",
      "yyy~~~~~~~~~~yyy",
      "yyyC~~~~~~!!!yyy",
      "yyy~~~~~~~!!4yyy",
      "yyyC~~~~~~!!!yyy",
      "yyy~~~~~~~~~~yyy",
      "yyyC~~~~~yyyyyyy",
      "yyy~~~~~~~~~~yyy",
      "yyy~~~~~~~~~~yyy",
      "yyy~~~~~~~~~~yyy",
      "yyy~~~~~~~~~~yyy",
      "yyyyyy~~yyyyyyyy"
    ],
    [
      "yyyyyy~~yyyyyyyy",
      "yyy~~~~~~~~~~yyy",
      "yyy~~~~~~~~~~yyy",
      "yyy~~~~~~~~~~yyy",
      "yyy~~~~~~yyyyyyy",
      "yyy~~~~~~~~~~yyy",
      "yyy~~~~~~~!!!yyy",
      "yyy~~~~~~~!!!yyy",
      "yyy~~~~~~~!!!yyy",
      "yyy~~~~~~~~~~yyy",
      "yyy~~~~~~yyyyyyy",
      "yyy~~~~~~~~~~yyy",
      "yyy~~~~~~~~~~yyy",
      "yyy~~~~~~~~~~yyy",
      "yyy~~~~~~~~~~yyy",
      "yyyyyy~~yyyyyyyy"
    ],
    [
      "yyyyyyyyyyyyyyyy",
      "yyy~~~~~~~~~~yyy",
      "yyy~~~~~~~~~~yyy",
      "yyy~~~~~~~~~~yyy",
      "yyy~~~~~~yyyyyyy",
      "yyy~~~~~~~~~~yyy",
      "yyy~~~~~~~~~~yyy",
      "yyy~~~~~~~~~~yyy",
      "yyy~~~~~~~~~~yyy",
      "yyy~~~~~~~~~~yyy",
      "yyy~~~~~~yyyyyyy",
      "yyy~~~~~~~~~~yyy",
      "yyy~~~~~~~~~~yyy",
      "yyy~~~~~~~~~~yyy",
      "yyy~~~~~~~~~~yyy",
      "yyyyyyyyyyyyyyyy"
    ],
    [
      "yyyyyyyyyyyyyyyy",
      "yyyyyyyyyyyyyyyy",
      "yyyyyyyyyyyyyyyy",
      "yyyyyyyyyyyyyyyy",
      "yyyyyyyyyyyyyyyy",
      "yyyyyyyyyyyyyyyy",
      "yyyyyyyyyyyyyyyy",
      "yyyyyyyyyyyyyyyy",
      "yyyyyyyyyyyyyyyy",
      "yyyyyyyyyyyyyyyy",
      "yyyyyyyyyyyyyyyy",
      "yyyyyyyyyyyyyyyy",
      "yyyyyyyyyyyyyyyy",
      "yyyyyyyyyyyyyyyy",
      "yyyyyyyyyyyyyyyy",
      "yyyyyyyyyyyyyyyy"
    ]
  ]
}