{
  "xsize": 16,
  "zsize": 16,
  "refpalette": "rails",
  "slices": [
    [
      "                ",
      "                ",
      "                ",
      "yy              ",
      "yy              ",
      "yy              ",
      "yyy             ",
      "yy              ",
      "yyy             ",
      "yy              ",
      "yy              ",
      "yy              ",
      "                ",
      "                ",
      "                ",
      "                "
    ],
    [
      "                ",
      "                ",
      "                ",
      "yyy             ",
      "yyy             ",
      "fiy             ",
      "yyg             ",
      "fiy             ",
      "yyg             ",
      "fiy             ",
      "yyy             ",
      "yyy             ",
      "                ",
      "                ",
      "                ",
      "                "
    ],
    [
      "                ",
      "                ",
      "                ",
      "yyyy            ",
      "~~yy            ",
      "~~iy            ",
      "~~yy            ",
      "~~iy            ",
      "~~yy            ",
      "~~iy            ",
      "~~yy            ",
      "yyyy            ",
      "                ",
      "                ",
      "                ",
      "                "
    ],
    [
      "                ",
      "                ",
      "                ",
      "yyyyy           ",
      "~~~yy           ",
      "~~~jy           ",
      "~~~yy           ",
      "~~~jy           ",
      "~~~yy           ",
      "~~~jy           ",
      "~~~yy           ",
      "yyyyy           ",
      "                ",
      "                ",
      "                ",
      "                "
    ],
    [
      "                ",
      "                ",
      "                ",
      "yyyyyy          ",
      "~~~~yy          ",
      "~~~~jy          ",
      "~~~~yy          ",
      "~~~~jy          ",
      "~~~~yy          ",
      "~~~~jy          ",
      "~~~~yy          ",
      "yyyyyy          ",
      "                ",
      "                ",
      "                ",
      "                "
    ],
    [
      "                ",
      "                ",
      "                ",
      "yyyyyyy         ",
      "y~~~~yy         ",
      "y~~~~jy         ",
      "y~~~~yy         ",
      "y~~~~jy         ",
      "y~~~~yy         ",
      "y~~~~jy         ",
      "y~~~~yy         ",
      "yyyyyyy         ",
      "                ",
      "                ",
      "                ",
      "                "
    ],
    [
      "                ",
      "                ",
      "                ",
      " yyyyyyy        ",
      " y~~~~yy        ",
      " y~~~~jy        ",
      " y~~~~yy        ",
      " y~~~~jy        ",
      " y~~~~yy        ",
      " y~~~~jy        ",
      " y~~~~yy        ",
      " yyyyyyy        ",
      "                ",
      "                ",
      "                ",
      "                "
    ],
    [
      "                ",
      "                ",
      "                ",
      "  yyyyyyy       ",
      "  y~~~~yy       ",
      "  y~~~~iy       ",
      "  y~~~~yyy      ",
      "  y~~~~iy       ",
      "  y~~~~yyy      ",
      "  y~~~~iy       ",
      "  y~~~~yy       ",
      "  yyyyyyy       ",
      "                ",
      "                ",
      "                ",
      "                "
    ],
    [
      "                ",
      "                ",
      "                ",
      "   yyyyyyy      ",
      "   y~~~~yy      ",
      "   y~~~~iy      ",
      "   y~~~~yg      ",
      "   y~~~~iy      ",
      "   y~~~~yg      ",
      "   y~~~~iy      ",
      "   y~~~~yy      ",
      "   yyyyyyy      ",
      "                ",
      "                ",
      "                ",
      "                "
    ],
    [
      "                ",
      "                ",
      "                ",
      "    yyyyyyy     ",
      "    y~~~~yy     ",
      "    y~~~~iy     ",
      "    y~~~~yy     ",
      "    y~~~~iy     ",
      "    y~~~~yy     ",
      "    y~~~~iy     ",
      "    y~~~~yy     ",
      "    yyyyyyy     ",
      "                ",
      "                ",
      "                ",
      "                "
    ],
    [
      "                ",
      "                ",
      "                ",
      "     yyyyyyy    ",
      "     y~~~~yy    ",
      "     y~~~~jy    ",
      "     y~~~~yy    ",
      "     y~~~~jy    ",
      "     y~~~~yy    ",
      "     y~~~~jy    ",
      "     y~~~~yy    ",
      "     yyyyyyy    ",
      "                ",
      "                ",
      "                ",
      "                "
    ],
    [
      "                ",
      "                ",
      "                ",
      "      yyyyyyy   ",
      "      y~~~~yy   ",
      "      y~~~~jy   ",
      "      y~~~~yy y ",
      "      y~~~~jy   ",
      "      y~~~~yy y ",
      "      y~~~~jy   ",
      "      y~~~~yy   ",
      "      yyyyyyy   ",
      "                ",
      "                ",
      "                ",
      "                "
    ],
    [
      "                ",
      "                ",
      "                ",
      "       yyyyyyyyy",
      "       y~~~~yyyy",
      "       y~~~~jyyy",
      "       y~~~~yygy",
      "       y~~~~jyyy",
      "       y~~~~yygy",
      "       y~~~~jyyy",
      "       y~~~~yyyy",
      "       yyyyyyyyy",
      "                ",
      "                ",
      "                ",
      "                "
    ],
    [
      "                ",
      "                ",
      "                ",
      "        yyyyyyyy",
      "        y~~~~yyy",
      "        y~~~~fff",
      "        y~~~~yyy",
      "        y~~~~fff",
      "        y~~~~yyy",
      "        y~~~~fff",
      "        y~~~~yyy",
      "        yyyyyyyy",
      "                ",
      "                ",
      "                ",
      "                "
    ],
    [
      "                ",
      "                ",
      "                ",
      "         yyyyyyy",
      "         y~~~~~~",
      "         y~~~~~~",
      "         y~~~~~~",
      "         y~~~~~~",
      "         y~~~~~~",
      "         y~~~~~~",
      "         y~~~~~~",
      "         yyyyyyy",
      "                ",
      "                ",
      "                ",
      "                "
    ],
    [
      "                ",
      "                ",
      "                ",
      "          yyyyyy",
      "          y~~~~~",
      "          y~~~~~",
      "          y~~~~~",
      "          y~~~~~",
      "          y~~~~~",
      "          y~~~~~",
      "          y~~~~~",
      "          yyyyyy",
      "                ",
      "                ",
      "                ",
      "                "
    ],
    [
      "                ",
      "                ",
      "                ",
      "           yyyyy",
      "           y~~~~",
      "           y~~~~",
      "           y~~~~",
      "           y~~~~",
      "           y~~~~",
      "           y~~~~",
      "           y~~~~",
      "           yyyyy",
      "                ",
      "                ",
      "                ",
      "                "
    ],
    [
      "                ",
      "                ",
      "                ",
      "            yyyy",
      "            yyyy",
      "            yyyy",
      "            yyyy",
      "            yyyy",
      "            yyyy",
      "            yyyy",
      "            yyyy",
      "            yyyy",
      "                ",
      "                ",
      "                ",
      "                "
    ]
  ]
}