{
  "xsize": 16,
  "zsize": 16,
  "refpalette": "rails",
  "slices": [
    [
      "                ",
      "                ",
      "                ",
      "yyyyyyyyyyyyyyyy",
      "yyyyyyyyyyyyyyyy",
      "yyyyyyyyyyyyyyyy",
      "yyyyyyyyyyyyyyyy",
      "yyyyyyyyyyyyyyyy",
      "yyyyyyyyyyyyyyyy",
      "yyyyyyyyyyyyyyyy",
      "yyyyyyyyyyyyyyyy",
      "yyyyyyyyyyyyyyyy",
      "                ",
      "                ",
      "                ",
      "                "
    ],
    [
      "                ",
      "                ",
      "                ",
      "yyyyyyyyyyyyyyyy",
      "yyyyyyyyyyyyyyyy",
      "eeeeeeefeeeeeeee",
      "yyyyyyygyyyyyyyy",
      "eeeeeeefeeeeeeee",
      "yyyyyyygyyyyyyyy",
      "eeeeeeefeeeeeeee",
      "yyyyyyyyyyyyyyyy",
      "yyyyyyyyyyyyyyyy",
      "                ",
      "                ",
      "                ",
      "                "
    ],
    [
      "                ",
      "                ",
      "                ",
      "yyyyyyyyyyyyyyyy",
      "~~~~~~~~~~~~~~~~",
      "~~~~~~~~~~~~~~~~",
      "~~~~~~~~~~~~~~~~",
      "~~~~~~~~~~~~~~~~",
      "~~~~~~~~~~~~~~~~",
      "~~~~~~~~~~~~~~~~",
      "~~~~~~~~~~~~~~~~",
      "yyyyyyyyyyyyyyyy",
      "                ",
      "                ",
      "                ",
      "                "
    ],
    [
      "                ",
      "                ",
      "                ",
      "++++++++++++++++",
      "~~~~~~~~~~~~~~~~",
      "~~~~~~~~~~~~~~~~",
      "~~~~~~~~~~~~~~~~",
      "~~~~~~~~~~~~~~~~",
      "~~~~~~~~~~~~~~~~",
      "~~~~~~~~~~~~~~~~",
      "~~~~~~~~~~~~~~~~",
      "++++++++++++++++",
      "                ",
      "                ",
      "                ",
      "                "
    ],
    [
      "                ",
      "                ",
      "                ",
      "++++++++++++++++",
      "~~~~~~~~~~~~~~~~",
      "~~~~~~~~~~~~~~~~",
      "~~~~~~~~~~~~~~~~",
      "~~~~~~~~~~~~~~~~",
      "~~~~~~~~~~~~~~~~",
      "~~~~~~~~~~~~~~~~",
      "~~~~~~~~~~~~~~~~",
      "++++++++++++++++",
      "                ",
      "                ",
      "                ",
      "                "
    ],
    [
      "                ",
      "                ",
      "                ",
      "yyyyyyyyyyyyyyyy",
      "yyyyyyyyyyyyyyyy",
      "++++++++++++++++",
      "++++++++++++++++",
      "++++++++++++++++",
      "++++++++++++++++",
      "++++++++++++++++",
      "yyyyyyyyyyyyyyyy",
      "yyyyyyyyyyyyyyyy",
      "                ",
      "                ",
      "                ",
      "                "
    ]
  ]
}