{
  "xsize": 16,
  "zsize": 16,
  "refpalette": "rails",
  "slices": [
    [
      "                ",
      "                ",
      "                ",
      "y               ",
      "y               ",
      "y               ",
      "y               ",
      "y               ",
      "y               ",
      "y               ",
      "y               ",
      "y               ",
      "                ",
      "                ",
      "                ",
      "                "
    ],
    [
      "                ",
      "                ",
      "                ",
      "yy              ",
      "yy              ",
      "jy              ",
      "yy              ",
      "jy              ",
      "yy              ",
      "jy              ",
      "yy              ",
      "yy              ",
      "                ",
      "                ",
      "                ",
      "                "
    ],
    [
      "                ",
      "                ",
      "                ",
      "yyy             ",
      "~yy             ",
      "~jy             ",
      "~yy             ",
      "~jy             ",
      "~yy             ",
      "~jy             ",
      "~yy             ",
      "yyy             ",
      "                ",
      "                ",
      "                ",
      "                "
    ],
    [
      "                ",
      "                ",
      "                ",
      "yyyy            ",
      "~~yy            ",
      "~~jy            ",
      "~~yy            ",
      "~~jy            ",
      "~~yy            ",
      "~~jy            ",
      "~~yy            ",
      "yyyy            ",
      "                ",
      "                ",
      "                ",
      "                "
    ],
    [
      "                ",
      "                ",
      "                ",
      "yyyyy           ",
      "~~~yy           ",
      "~~~jy           ",
      "~~~yy           ",
      "~~~jy           ",
      "~~~yy           ",
      "~~~jy           ",
      "~~~yy           ",
      "yyyyy           ",
      "                ",
      "                ",
      "                ",
      "                "
    ],
    [
      "                ",
      "                ",
      "                ",
      "yyyyyy          ",
      "~~~~yy          ",
      "~~~~jy          ",
      "~~~~yy y        ",
      "~~~~jy          ",
      "~~~~yy y        ",
      "~~~~jy          ",
      "~~~~yy          ",
      "yyyyyy          ",
      "                ",
      "                ",
      "                ",
      "                "
    ],
    [
      "                ",
      "                ",
      "                ",
      "yyyyyyy         ",
      "y~~~~yyyyyyyyyyy",
      "y~~~~jyyyyyyyyyy",
      "y~~~~yygyyyyyyyy",
      "y~~~~jyyyyyyyyyy",
      "y~~~~yygyyyyyyyy",
      "y~~~~jyyyyyyyyyy",
      "y~~~~yyyyyyyyyyy",
      "yyyyyyy         ",
      "                ",
      "                ",
      "                ",
      "                "
    ],
    [
      "               y",
      "               y",
      "               y",
      " yyyyyy        y",
      " y~~~~yyyyyyyyyy",
      " y~~~~efeeeeeeee",
      " y~~~~yyyyyyyyyy",
      " y~~~~efeeeeeeee",
      " y~~~~yyyyyyyyyy",
      " y~~~~efeeeeeeee",
      " y~~~~yyyyyyyyyy",
      " yyyyyy        y",
      "               y",
      "               y",
      "               y",
      "               y"
    ],
    [
      "                ",
      "                ",
      "                ",
      " y::::y         ",
      " :~~~~~~~~~~~~~~",
      " :~~~~~~~~~~~~~~",
      " :~~~~~~~~~~~~~~",
      " :~~~~~~~~~~~~~~",
      " :~~~~~~~~~~~~~~",
      " :~~~~~~~~~~~~~~",
      " :~~~~~~~~~~~~~~",
      " y::::y         ",
      "                ",
      "                ",
      "                ",
      "                "
    ],
    [
      "                ",
      "                ",
      "                ",
      " y::::y         ",
      " :~~~~~~~~~~~~~~",
      " :~~~~~~~~~~~~~~",
      " :~~~~~~~~~~~~~~",
      " :~~~~~~~~~~~~~~",
      " :~~~~~~~~~~~~~~",
      " :~~~~~~~~~~~~~~",
      " :~~~~~~~~~~~~~~",
      " y::::y         ",
      "                ",
      "                ",
      "                ",
      "                "
    ],
    [
      "                ",
      "                ",
      "                ",
      " y~~~~y         ",
      " ~~~~~~~~~~~~~~~",
      " ~~~~~~~~~~~~~~~",
      " ~~~~~~~~~~~~~~~",
      " ~~~~~~~~~~~~~~~",
      " ~~~~~~~~~~~~~~~",
      " ~~~~~~~~~~~~~~~",
      " ~~~~~~~~~~~~~~~",
      " y~~~~y         ",
      "                ",
      "                ",
      "                ",
      "                "
    ],
    [
      "                ",
      "                ",
      "                ",
      " ______         ",
      " _~~~~_~~~~~~~~~",
      " _~~~~_~~~~~~~~~",
      " _~~~~_~~~~~~~~~",
      " _~~~~_~~~~~~~~~",
      " _~~~~_~~~~~~~~~",
      " _~~~~_~~~~~~~~~",
      " _~~~~_~~~~~~~~~",
      " ______         ",
      "                ",
      "                ",
      "                ",
      "                "
    ]
  ]
}