{
  "meta": [
    {
      "key": "dontconnect",
      "boolean": true
    }
  ],
  "xsize": 16,
  "zsize": 16,
  "slices": [
    [
      "a   ####))))####",
      "a   #SSQQSSQQSSQ",
      "a   #QQSSQQSSQQS",
      "a   #QQSSQQSSQQS",
      "a   #SSQQSSQQSSQ",
      "a   #SSQQSSQQSSQ",
      "a   #QQSSQQSSQQS",
      "a   #QQSSQQSSQQS",
      "a   #SSQQSSQQSSQ",
      "a   #SSQQSSQQSSQ",
      "a   #QQSSQQSSQQS",
      "a   ############",
      "a               ",
      "a               ",
      "a               ",
      "aaaaaaaaaaaaaaaa"
    ],
    [
      "a   :::w    w:::",
      "a   :           ",
      "a   :           ",
      "a   :           ",
      "a   :           ",
      "a   :           ",
      "a   :           ",
      "a   :           ",
      "a   :           ",
      "a   :           ",
      "a   :           ",
      "a   ::::::::::::",
      "a               ",
      "a               ",
      "a               ",
      "aaaaaaaaaaaaaaaa"
    ],
    [
      "a      T    T   ",
      "a               ",
      "a               ",
      "a               ",
      "a               ",
      "a               ",
      "a               ",
      "a               ",
      "a               ",
      "a               ",
      "a               ",
      "a               ",
      "a               ",
      "a               ",
      "a               ",
      "aaaaaaaaaaaaaaaa"
    ],
    [
      "a               ",
      "a               ",
      "a               ",
      "a               ",
      "a               ",
      "a               ",
      "a               ",
      "a               ",
      "a               ",
      "a               ",
      "a               ",
      "a               ",
      "a               ",
      "a               ",
      "a               ",
      "aaaaaaaaaaaaaaaa"
    ],
    [
      "a               ",
      "a               ",
      "a               ",
      "a               ",
      "a               ",
      "a               ",
      "a               ",
      "a               ",
      "a               ",
      "a               ",
      "a               ",
      "a               ",
      "a               ",
      "a               ",
      "a               ",
      "aaaaaaaaaaaaaaaa"
    ],
    [
      "################",
      "################",
      "################",
      "################",
      "################",
      "################",
      "################",
      "################",
      "################",
      "################",
      "################",
      "################",
      "################",
      "################",
      "################",
      "################"
    ]
  ]
}