{
  "meta": [
    {
      "key": "dontconnect",
      "boolean": true
    }
  ],
  "xsize": 16,
  "zsize": 16,
  "slices": [
    [
      "a               ",
      "a               ",
      "a               ",
      "a               ",
      "a               ",
      "a               ",
      "a               ",
      "a               ",
      "a               ",
      "a               ",
      "a               ",
      "a               ",
      "a               ",
      "a               ",
      "a               ",
      "aaaaaaaaaaaaaaaa"
    ],
    [
      "a               ",
      "a               ",
      "a               ",
      "a               ",
      "a               ",
      "a               ",
      "a               ",
      "a               ",
      "a               ",
      "a               ",
      "a               ",
      "a               ",
      "a               ",
      "a               ",
      "a               ",
      "aaaaaaaaaaaaaaaa"
    ],
    [
      "a               ",
      "a               ",
      "a               ",
      "a               ",
      "a               ",
      "a               ",
      "a               ",
      "a               ",
      "a               ",
      "a               ",
      "a               ",
      "a               ",
      "a               ",
      "a               ",
      "a               ",
      "aaaaaaaaaaaaaaaa"
    ],
    [
      "a               ",
      "a               ",
      "a               ",
      "a               ",
      "a               ",
      "a               ",
      "a               ",
      "a               ",
      "a               ",
      "a               ",
      "a               ",
      "a               ",
      "a               ",
      "a               ",
      "a               ",
      "aaaaaaaaaaaaaaaa"
    ],
    [
      "a               ",
      "a               ",
      "a               ",
      "a               ",
      "a               ",
      "a               ",
      "a               ",
      "a               ",
      "a               ",
      "a               ",
      "a               ",
      "a               ",
      "a               ",
      "a               ",
      "a               ",
      "aaaaaaaaaaaaaaaa"
    ],
    [
      "a               ",
      "a               ",
      "a               ",
      "a               ",
      "a               ",
      "a               ",
      "a               ",
      "a               ",
      "a               ",
      "a               ",
      "a               ",
      "a               ",
      "a               ",
      "a               ",
      "a               ",
      "aaaaaaaaaaaaaaaa"
    ]
  ]
}