{
  "xsize": 16,
  "zsize": 16,
  "slices": [
    [
      "################",
      "#SSQQSSQQSSQQSSQ",
      "#SSQQSSQQSSQQSSQ",
      "#QQSSQQSSQQSSQQS",
      "#QQSSQQSSQQSSQQS",
      "#SSQQSSQQSSQQSSQ",
      "#SSQQSSQQSSQQSSQ",
      "#QQSSQQSSQQSSQQS",
      "#QQSSQQSSQQSSQQS",
      "#SSQQSSQQSSQQSSQ",
      "#SSQQSSQQSSQQSSQ",
      "#QQSSQQSSQQSSQQS",
      "#QQSSQQSSQQSSQQS",
      "#SSQQSSQQSSQQSSQ",
      "#SSQQSSQQSSQQSSQ",
      "#QQSSQQSSQQSSQQS"
    ],
    [
      "################",
      "#               ",
      "#               ",
      "#               ",
      "#               ",
      "#               ",
      "#               ",
      "#               ",
      "#               ",
      "#               ",
      "#               ",
      "#               ",
      "#               ",
      "#               ",
      "#               ",
      "#               "
    ],
    [
      "################",
      "#               ",
      "#               ",
      "#               ",
      "#               ",
      "#               ",
      "#               ",
      "#               ",
      "#               ",
      "#               ",
      "#               ",
      "#               ",
      "#               ",
      "#               ",
      "#               ",
      "#               "
    ],
    [
      "###aa#aa#aa#aa#a",
      "#               ",
      "#               ",
      "a               ",
      "a               ",
      "#               ",
      "a               ",
      "a               ",
      "#               ",
      "a               ",
      "a               ",
      "#               ",
      "a               ",
      "a               ",
      "#               ",
      "a               "
    ],
    [
      "################",
      "#               ",
      "#               ",
      "#               ",
      "#               ",
      "#               ",
      "#               ",
      "#               ",
      "#               ",
      "#               ",
      "#               ",
      "#               ",
      "#               ",
      "#               ",
      "#               ",
      "#               "
    ],
    [
      "################",
      "################",
      "################",
      "################",
      "################",
      "################",
      "################",
      "################",
      "################",
      "################",
      "################",
      "################",
      "################",
      "################",
      "################",
      "################"
    ]
  ]
}