{
  "meta": [
    {
      "integer": 5,
      "key": "z1"
    },
    {
      "integer": 10,
      "key": "z2"
    }
  ],
  "xsize": 6,
  "zsize": 11,
  "slices": [
    [
      "      ",
      "      ",
      "      ",
      "      ",
      "      ",
      "xxxxxx",
      "xxxxx/",
      "xxxxx/",
      "xxxxx/",
      "xxxxx/",
      "xxxxxx"
    ],
    [
      "      ",
      "      ",
      "      ",
      "      ",
      "      ",
      "xxxxx_",
      "xxxx/ ",
      "xxxx/ ",
      "xxxx/ ",
      "xxxx/ ",
      "xxxxx_"
    ],
    [
      "      ",
      "      ",
      "      ",
      "      ",
      "      ",
      "xxxx_ ",
      "xxx/  ",
      "xxx/  ",
      "xxx/  ",
      "xxx/  ",
      "xxxx_ "
    ],
    [
      "      ",
      "      ",
      "      ",
      "      ",
      "      ",
      "xxx_  ",
      "xx/   ",
      "xx/   ",
      "xx/   ",
      "xx/   ",
      "xxx_  "
    ],
    [
      "      ",
      "      ",
      "      ",
      "      ",
      "      ",
      "xx_   ",
      "x/    ",
      "x/    ",
      "x/    ",
      "x/    ",
      "xx_   "
    ],
    [
      "      ",
      "      ",
      "      ",
      "      ",
      "      ",
      "x_    ",
      "/     ",
      "/     ",
      "/     ",
      "/     ",
      "x_    "
    ],
    [
      "      ",
      "      ",
      "      ",
      "      ",
      "      ",
      "_     ",
      "      ",
      "      ",
      "      ",
      "      ",
      "_     "
    ]
  ]
}