{
  "xsize": 16,
  "zsize": 16,
  "refpalette": "rails",
  "slices": [
    [
      "                ",
      "                ",
      "                ",
      "                ",
      "                ",
      "                ",
      "                ",
      "                ",
      "                ",
      "                ",
      "yyyyyyyyyyy     ",
      "yQQQQQQQQQy     ",
      "yQQQQQQQQQy     ",
      "yQQQ~~~~~=y     ",
      "yQQQ~~~~~=y     ",
      "yyyyyyyyyyy     "
    ],
    [
      "                ",
      "                ",
      "                ",
      "                ",
      "                ",
      "                ",
      "                ",
      "                ",
      "                ",
      "                ",
      "y~~~~~~~~~y     ",
      ":~~~~~~~~~~     ",
      ":~~~~~~~~~~     ",
      ":~~~~~~~~~~     ",
      ":~~~~~~~~~~     ",
      "y:::::::::y     "
    ],
    [
      "                ",
      "                ",
      "                ",
      "                ",
      "                ",
      "                ",
      "                ",
      "                ",
      "                ",
      "                ",
      "y~~~~~~~~~y     ",
      ":~~~~~~~~~~     ",
      ":~~~~~~~~~~     ",
      ":~~~~~~~~~~     ",
      ":~~~~~~~~~~     ",
      "y:::::::::y     "
    ],
    [
      "                ",
      "                ",
      "                ",
      "                ",
      "                ",
      "                ",
      "                ",
      "                ",
      "                ",
      "                ",
      "y~~~~~~~~~y     ",
      ":~~~~~~~~~~     ",
      ":~~~~~~~~~~     ",
      ":~~~~~~~~~~     ",
      ":~~~~~~~~~~     ",
      "y:::::::::y     "
    ],
    [
      "                ",
      "                ",
      "                ",
      "                ",
      "                ",
      "                ",
      "                ",
      "                ",
      "                ",
      "                ",
      "___________     ",
      "___________     ",
      "___________     ",
      "___________     ",
      "___________     ",
      "___________     "
    ]
  ]
}