{
  "xsize": 16,
  "zsize": 16,
  "refpalette": "rails",
  "slices": [
    [
      "yyyyyyyyyyyyyyyy",
      "yyyyyyyyyyyyyyyy",
      "yyyyyyyyyyyyyyyy",
      "yyyyyyyyyyyyyyyy",
      "yyyyyyyyyyyyyyyy",
      "yyyyyyyyyyyyyyyy",
      "yyyyyyyyyyyyyyyy",
      "yyyyyyyyyyyyyyyy",
      "yyyyyyyyyyyyyyyy",
      "yyyyyyyyyyyyyyyy",
      "yyyyyyyyyyyyyyyy",
      "yyyyyyyyyyyyyyyy",
      "yyyyyyyyyyyyyyyy",
      "yyyyyyyyyyyyyyyy",
      "yyyyyyyyyyyyyyyy",
      "yyyyyyyyyyyyyyyy"
    ],
    [
      "yyyyyyyyyyyyyyyy",
      "QQQQQQQQQQQQQQQQ",
      "QQQQQQQQQQQQQQQQ",
      "QQQQQQQQQQQQQQQQ",
      "yyyyyyyyyyyyyyyy",
      "eeeeeeefeeeeeeee",
      "yyyyyyygyyyyyyyy",
      "eeeeeeefeeeeeeee",
      "yyyyyyygyyyyyyyy",
      "eeeeeeefeeeeeeee",
      "yyyyyyyyyyyyyyyy",
      "QQQQQQQQQQQQQQQQ",
      "QQQQQQQQQQQQQQQQ",
      "QQQQQQQQQQQQQQQQ",
      "QQQQQQQQQQQQQQQQ",
      "yyyyyyyyyyyyyyyy"
    ],
    [
      "yyyyyyyyyyyyyyyy",
      "~~~~~~~~~~~~~~~~",
      "~~~~~~~~~~~~~~~~",
      "~~~~~~~~~~~~~~~~",
      "~~~~~~~~~~~~~~~~",
      "~~~~~~~~~~~~~~~~",
      "~~~~~~~~~~~~~~~~",
      "~~~~~~~~~~~~~~~~",
      "~~~~~~~~~~~~~~~~",
      "~~~~~~~~~~~~~~~~",
      "~~~~~~~~~~~~~~~~",
      "~~~~~~~~~~~~~~~~",
      "~~~~~yyyyy~~~~~~",
      "~~~~~=yyyy~~~~~~",
      "~~~~~=yyyy~~~~~~",
      "yyyyyyyyyyyyyyyy"
    ],
    [
      "yyyyyyyyyyyyyyyy",
      "~~~~~~~~~~~~~~~~",
      "~~~~~~~~~~~~~~~~",
      "~~~~~~~~~~~~~~~~",
      "~~~~~~~~~~~~~~~~",
      "~~~~~~~~~~~~~~~~",
      "~~~~~~~~~~~~~~~~",
      "~~~~~~~~~~~~~~~~",
      "~~~~~~~~~~~~~~~~",
      "~~~~~~~~~~~~~~~~",
      "~~~~~~~~~~~~~~~~",
      "~~~~~~~~~~~~~~~~",
      "~~~~~yyyyy~~~~~~",
      "~~~~~~=yyy~~~~~~",
      "~~~~~~=yyy~~~~~~",
      "yyyyyyyyyyyyyyyy"
    ],
    [
      "yyhyyyyyyyyyyhyy",
      "~~~~~~~~~~~~~~~~",
      "~~~~~~~~~~~~~~~~",
      "~~~~~~~~~~~~~~~~",
      "~~~~~~~~~~~~~~~~",
      "~~~~~~~~~~~~~~~~",
      "~~~~~~~~~~~~~~~~",
      "~~~~~~~~~~~~~~~~",
      "~~~~~~~~~~~~~~~~",
      "~~~~~~~~~~~~~~~~",
      "~~~~~~~~~~~~~~~~",
      "~~~~~~~~~~~~~~~~",
      "~~~~~yyyyy~~~~~~",
      "~~~~~~~=yy~~~~~~",
      "~~~~~~~=yy~~~~~~",
      "yyhyyyyyyyyyyhyy"
    ],
    [
      "yyyyyyyyyyyyyyyy",
      "yyyyyyyyyyyyyyyy",
      "yyyyyyyyyyyyyyyy",
      "yyyyyyyyyyyyyyyy",
      "yyyyyyyyyyyyyyyy",
      "yyyyyyyyyyyyyyyy",
      "yyyyyyyyyyyyyyyy",
      "yyyyyyyyyyyyyyyy",
      "yyyyyyyyyyyyyyyy",
      "yyyyyyyyyyyyyyyy",
      "yyyyyyyyyyyyyyyy",
      "yyyyyyyyyyyyyyyy",
      "yyyyyyyyyyyyyyyy",
      "yyyy~~~~=yyyyyyy",
      "yyyy~~~~=yyyyyyy",
      "yyyyyyyyyyyyyyyy"
    ]
  ]
}