{
  "meta": [
    {
      "integer": 4,
      "key": "z1"
    },
    {
      "integer": 11,
      "key": "z2"
    }
  ],
  "xsize": 16,
  "zsize": 16,
  "slices": [
    [
      "bbbbbbbbbbbbbbbb",
      "bbbbbbbbbbbbbbbb",
      "bbbbbbbbbbbbbbbb",
      "bbbbbbbbbbbbbbbb",
      "SSSSSSSSSSSSSSSS",
      "SSSSSSSSSSSSSSSS",
      "SSSSSSSSSSSSSSSS",
      "SSSSSSSSSSSSSSSS",
      "SSSSSSSSSSSSSSSS",
      "SSSSSSSSSSSSSSSS",
      "SSSSSSSSSSSSSSSS",
      "SSSSSSSSSSSSSSSS",
      "bbbbbbbbbbbbbbbb",
      "bbbbbbbbbbbbbbbb",
      "bbbbbbbbbbbbbbbb",
      "bbbbbbbbbbbbbbbb"
    ],
    [
      "bbbbbbbbbbbbbbbb",
      "bbbbbbbbbbbbbbbb",
      "bbbbbbbbbbbbbbbb",
      "bbbbbbbbbbbbbbbb",
      "SSSSSSSSSSSSS_bb",
      "SSSSSSSSSSSSS_bb",
      "SSSSSSSSSSSSS_bb",
      "SSSSSSSSSSSSS_bb",
      "SSSSSSSSSSSSS_bb",
      "SSSSSSSSSSSSS_bb",
      "SSSSSSSSSSSSS_bb",
      "SSSSSSSSSSSSS_bb",
      "bbbbbbbbbbbbbbbb",
      "bbbbbbbbbbbbbbbb",
      "bbbbbbbbbbbbbbbb",
      "bbbbbbbbbbbbbbbb"
    ],
    [
      "bbbbbbbbbbbbbbbb",
      "bbbbbbbbbbbbbbbb",
      "bbbbbbbbbbbbbbbb",
      "bbbbbbbbbbbbbbbb",
      "SSSSSSSSSSS_bbbb",
      "SSSSSSSSSSS_bbbb",
      "SSSSSSSSSSS_bbbb",
      "SSSSSSSSSSS_bbbb",
      "SSSSSSSSSSS_bbbb",
      "SSSSSSSSSSS_bbbb",
      "SSSSSSSSSSS_bbbb",
      "SSSSSSSSSSS_bbbb",
      "bbbbbbbbbbbbbbbb",
      "bbbbbbbbbbbbbbbb",
      "bbbbbbbbbbbbbbbb",
      "bbbbbbbbbbbbbbbb"
    ],
    [
      "bbbbbbbbbbbbbbbb",
      "bbbbbbbbbbbbbbbb",
      "bbbbbbbbbbbbbbbb",
      "bbbbbbbbbbbbbbbb",
      "SSSSSSSSS_bbbbbb",
      "SSSSSSSSS_bbbbbb",
      "SSSSSSSSS_bbbbbb",
      "SSSSSSSSS_bbbbbb",
      "SSSSSSSSS_bbbbbb",
      "SSSSSSSSS_bbbbbb",
      "SSSSSSSSS_bbbbbb",
      "SSSSSSSSS_bbbbbb",
      "bbbbbbbbbbbbbbbb",
      "bbbbbbbbbbbbbbbb",
      "bbbbbbbbbbbbbbbb",
      "bbbbbbbbbbbbbbbb"
    ],
    [
      "bbbbbbbbbbbbbbbb",
      "bbbbbbbbbbbbbbbb",
      "bbbbbbbbbbbbbbbb",
      "bbbbbbbbbbbbbbbb",
      "SSSSSSS_bbbbbbbb",
      "SSSSSSS_bbbbbbbb",
      "SSSSSSS_bbbbbbbb",
      "SSSSSSS_bbbbbbbb",
      "SSSSSSS_bbbbbbbb",
      "SSSSSSS_bbbbbbbb",
      "SSSSSSS_bbbbbbbb",
      "SSSSSSS_bbbbbbbb",
      "bbbbbbbbbbbbbbbb",
      "bbbbbbbbbbbbbbbb",
      "bbbbbbbbbbbbbbbb",
      "bbbbbbbbbbbbbbbb"
    ],
    [
      "bbbbbbbbbbbbbbbb",
      "bbbbbbbbbbbbbbbb",
      "bbbbbbbbbbbbbbbb",
      "bbbbbbbbbbbbbbbb",
      "SSSSS_bbbbbbbbbb",
      "SSSSS_bbbbbbbbbb",
      "SSSSS_bbbbbbbbbb",
      "SSSSS_bbbbbbbbbb",
      "SSSSS_bbbbbbbbbb",
      "SSSSS_bbbbbbbbbb",
      "SSSSS_bbbbbbbbbb",
      "SSSSS_bbbbbbbbbb",
      "bbbbbbbbbbbbbbbb",
      "bbbbbbbbbbbbbbbb",
      "bbbbbbbbbbbbbbbb",
      "bbbbbbbbbbbbbbbb"
    ],
    [
      "bbbbbbbbbbbbbbbb",
      "bbbbbbbbbbbbbbbb",
      "bbbbbbbbbbbbbbbb",
      "bbbbbbbbbbbbbbbb",
      "SSS_bbbbbbbbbbbb",
      "SSS_bbbbbbbbbbbb",
      "SSS_bbbbbbbbbbbb",
      "SSS_bbbbbbbbbbbb",
      "SSS_bbbbbbbbbbbb",
      "SSS_bbbbbbbbbbbb",
      "SSS_bbbbbbbbbbbb",
      "SSS_bbbbbbbbbbbb",
      "bbbbbbbbbbbbbbbb",
      "bbbbbbbbbbbbbbbb",
      "bbbbbbbbbbbbbbbb",
      "bbbbbbbbbbbbbbbb"
    ]
  ]
}
