{
  "meta": [
    {
      "integer": 1,
      "key": "z1"
    },
    {
      "integer": 14,
      "key": "z2"
    }
  ],
  "xsize": 16,
  "zsize": 16,
  "refpalette": "street_large",
  "slices": [
    [
      "bbbbbbbbbbbbbbbb",
      "llllllllllllllll",
      "llllllllllllllll",
      "llllllllllllllll",
      "llllllllllllllll",
      "llllllllllllllll",
      "llllllllllllllll",
      "qqqqqqqqqqqqqqqq",
      "qqqqqqqqqqqqqqqq",
      "llllllllllllllll",
      "llllllllllllllll",
      "llllllllllllllll",
      "llllllllllllllll",
      "llllllllllllllll",
      "llllllllllllllll",
      "bbbbbbbbbbbbbbbb"
    ],
    [
      "bbbbbbbbbbbbbbbb",
      "lllllllllllll_bb",
      "lllllllllllll_bb",
      "lllllllllllll_bb",
      "lllllllllllll_bb",
      "lllllllllllll_bb",
      "lllllllllllll_bb",
      "qqqqqqqqqqqqq_bb",
      "qqqqqqqqqqqqq_bb",
      "lllllllllllll_bb",
      "lllllllllllll_bb",
      "lllllllllllll_bb",
      "lllllllllllll_bb",
      "lllllllllllll_bb",
      "lllllllllllll_bb",
      "bbbbbbbbbbbbbbbb"
    ],
    [
      "bbbbbbbbbbbbbbbb",
      "lllllllllll_bbbb",
      "lllllllllll_bbbb",
      "lllllllllll_bbbb",
      "lllllllllll_bbbb",
      "lllllllllll_bbbb",
      "lllllllllll_bbbb",
      "qqqqqqqqqqq_bbbb",
      "qqqqqqqqqqq_bbbb",
      "lllllllllll_bbbb",
      "lllllllllll_bbbb",
      "lllllllllll_bbbb",
      "lllllllllll_bbbb",
      "lllllllllll_bbbb",
      "lllllllllll_bbbb",
      "bbbbbbbbbbbbbbbb"
    ],
    [
      "bbbbbbbbbbbbbbbb",
      "lllllllll_bbbbbb",
      "lllllllll_bbbbbb",
      "lllllllll_bbbbbb",
      "lllllllll_bbbbbb",
      "lllllllll_bbbbbb",
      "lllllllll_bbbbbb",
      "qqqqqqqqq_bbbbbb",
      "qqqqqqqqq_bbbbbb",
      "lllllllll_bbbbbb",
      "lllllllll_bbbbbb",
      "lllllllll_bbbbbb",
      "lllllllll_bbbbbb",
      "lllllllll_bbbbbb",
      "lllllllll_bbbbbb",
      "bbbbbbbbbbbbbbbb"
    ],
    [
      "bbbbbbbbbbbbbbbb",
      "lllllll_bbbbbbbb",
      "lllllll_bbbbbbbb",
      "lllllll_bbbbbbbb",
      "lllllll_bbbbbbbb",
      "lllllll_bbbbbbbb",
      "lllllll_bbbbbbbb",
      "qqqqqqq_bbbbbbbb",
      "qqqqqqq_bbbbbbbb",
      "lllllll_bbbbbbbb",
      "lllllll_bbbbbbbb",
      "lllllll_bbbbbbbb",
      "lllllll_bbbbbbbb",
      "lllllll_bbbbbbbb",
      "lllllll_bbbbbbbb",
      "bbbbbbbbbbbbbbbb"
    ],
    [
      "bbbbbbbbbbbbbbbb",
      "lllll_bbbbbbbbbb",
      "lllll_bbbbbbbbbb",
      "lllll_bbbbbbbbbb",
      "lllll_bbbbbbbbbb",
      "lllll_bbbbbbbbbb",
      "lllll_bbbbbbbbbb",
      "qqqqq_bbbbbbbbbb",
      "qqqqq_bbbbbbbbbb",
      "lllll_bbbbbbbbbb",
      "lllll_bbbbbbbbbb",
      "lllll_bbbbbbbbbb",
      "lllll_bbbbbbbbbb",
      "lllll_bbbbbbbbbb",
      "lllll_bbbbbbbbbb",
      "bbbbbbbbbbbbbbbb"
    ],
    [
      "bbbbbbbbbbbbbbbb",
      "lll_bbbbbbbbbbbb",
      "lll_bbbbbbbbbbbb",
      "lll_bbbbbbbbbbbb",
      "lll_bbbbbbbbbbbb",
      "lll_bbbbbbbbbbbb",
      "lll_bbbbbbbbbbbb",
      "qqq_bbbbbbbbbbbb",
      "qqq_bbbbbbbbbbbb",
      "lll_bbbbbbbbbbbb",
      "lll_bbbbbbbbbbbb",
      "lll_bbbbbbbbbbbb",
      "lll_bbbbbbbbbbbb",
      "lll_bbbbbbbbbbbb",
      "lll_bbbbbbbbbbbb",
      "bbbbbbbbbbbbbbbb"
    ]
  ]
}
