{
  "xsize": 16,
  "zsize": 16,
  "slices": [
    [
      "################",
      "#SQSQSQSQSQSQS##",
      "SQSQSQSQSQSQSQS#",
      "QSQSQSQSQSQSQSQ#",
      "SQSQSQSQSQSQSQS#",
      "QSQSQSQSQSQSQSQ#",
      "SQSQSQSQSQSQSQS#",
      "QSQSQSQSQSQSQSQ#",
      "SQSQSQSQSQSQSQS#",
      "QSQSQSQSQSQSQSQ#",
      "SQSQSQSQSQSQSQS#",
      "QSQSQSQSQSQSQSQ#",
      "SQSQSQSQSQSQSQS#",
      "QSQSQSQSQSQSQSQ#",
      "SQSQSQSQSQSQSQS#",
      "QSQSQSQSQSQSQS##"
    ],
    [
      "#aaaaaaaaaaaaa##",
      "#             ##",
      "               a",
      "               a",
      "               a",
      "               a",
      "               a",
      "               a",
      "               a",
      "               a",
      "               a",
      "               a",
      "               a",
      "               a",
      "               a",
      "              ##"
    ],
    [
      "#aaaaaaaaaaaaa##",
      "#             ##",
      "               a",
      "               a",
      "               a",
      "               a",
      "               a",
      "               a",
      "               a",
      "               a",
      "               a",
      "               a",
      "               a",
      "               a",
      "               a",
      "              ##"
    ],
    [
      "#aaaaaaaaaaaaa##",
      "#             ##",
      "               a",
      "               a",
      "               a",
      "               a",
      "               a",
      "               a",
      "               a",
      "               a",
      "               a",
      "               a",
      "               a",
      "               a",
      "               a",
      "              ##"
    ],
    [
      "#aaaaaaaaaaaaa##",
      "#             ##",
      "               a",
      "               a",
      "               a",
      "               a",
      "               a",
      "               a",
      "               a",
      "               a",
      "               a",
      "               a",
      "               a",
      "               a",
      "               a",
      "              ##"
    ],
    [
      "################",
      "################",
      "################",
      "################",
      "################",
      "################",
      "################",
      "################",
      "################",
      "################",
      "################",
      "################",
      "################",
      "################",
      "################",
      "################"
    ]
  ]
}