{
  "xsize": 16,
  "zsize": 16,
  "slices": [
    [
      "##SQSQSQSQSQSQSQ",
      "##QSQSQSQSQSQSQS",
      ":#SQSQSQSQSQSQSQ",
      ":#QSQSQSQSQSQSQS",
      "##SQSQSQSQSQSQSQ",
      "aSQSQSQSQSQSQSQS",
      "aQSQSQSQSQSQSQSQ",
      "aSQSQSQSQSQSQSQS",
      "aQSQSQSQSQSQSQSQ",
      "aSQSQSQSQSQSQSQS",
      "aQSQSQSQSQSQSQSQ",
      "##QSQSQSQSQSQSQS",
      ":#SQSQSQSQSQSQSQ",
      ":#QSQSQSQSQSQSQS",
      "#####QSQSQS#####",
      "##::#aaaaaa#::##"
    ],
    [
      "##              ",
      "##              ",
      ":a              ",
      ":a              ",
      "##              ",
      "a               ",
      "a               ",
      "a       T       ",
      "a               ",
      "a               ",
      "a               ",
      "##              ",
      ":a              ",
      ":a              ",
      "##aa#      #aa##",
      "##::#aaaaaa#::##"
    ],
    [
      "##              ",
      "##              ",
      ":a              ",
      ":a              ",
      "##              ",
      "a               ",
      "a               ",
      "a               ",
      "a               ",
      "a               ",
      "a               ",
      "##              ",
      ":a              ",
      ":a              ",
      "##aa#      #aa##",
      "##::#aaaaaa#::##"
    ],
    [
      "##              ",
      "##              ",
      ":a              ",
      ":a              ",
      "##              ",
      "a               ",
      "a               ",
      "a               ",
      "a               ",
      "a               ",
      "a               ",
      "##              ",
      ":a              ",
      ":a              ",
      "##aa#      #aa##",
      "##::#aaaaaa#::##"
    ],
    [
      "##              ",
      "##              ",
      ":a              ",
      ":a              ",
      "##              ",
      "a               ",
      "a               ",
      "a               ",
      "a               ",
      "a               ",
      "a               ",
      "##              ",
      ":a              ",
      ":a              ",
      "##aa#      #aa##",
      "##::#aaaaaa#::##"
    ],
    [
      "################",
      "################",
      ":###############",
      ":###############",
      "################",
      "a###############",
      "a###############",
      "a###############",
      "a###############",
      "a###############",
      "a###############",
      "################",
      ":###############",
      ":###############",
      "################",
      "##::#aaaaaa#::##"
    ]
  ]
}